Workbook
Name AWARDS_TEAMS: 'AWARDS_DATA'!$A$1:$A$48
Name PLAYERS_MEX: 'AWARDS_DATA'!$B$1:$B$26
Name PLAYERS_RSA: 'AWARDS_DATA'!$C$1:$C$26
Name PLAYERS_KOR: 'AWARDS_DATA'!$D$1:$D$26
Name PLAYERS_CZE: 'AWARDS_DATA'!$E$1:$E$26
Name PLAYERS_CAN: 'AWARDS_DATA'!$F$1:$F$26
Name PLAYERS_SUI: 'AWARDS_DATA'!$G$1:$G$26
Name PLAYERS_QAT: 'AWARDS_DATA'!$H$1:$H$26
Name PLAYERS_BIH: 'AWARDS_DATA'!$I$1:$I$26
Name PLAYERS_BRA: 'AWARDS_DATA'!$J$1:$J$26
Name PLAYERS_MAR: 'AWARDS_DATA'!$K$1:$K$26
Name PLAYERS_SCO: 'AWARDS_DATA'!$L$1:$L$26
Name PLAYERS_HAI: 'AWARDS_DATA'!$M$1:$M$26
Name PLAYERS_USA: 'AWARDS_DATA'!$N$1:$N$26
Name PLAYERS_PAR: 'AWARDS_DATA'!$O$1:$O$26
Name PLAYERS_AUS: 'AWARDS_DATA'!$P$1:$P$26
Name PLAYERS_TUR: 'AWARDS_DATA'!$Q$1:$Q$26
Name PLAYERS_GER: 'AWARDS_DATA'!$R$1:$R$26
Name PLAYERS_CUW: 'AWARDS_DATA'!$S$1:$S$26
Name PLAYERS_CIV: 'AWARDS_DATA'!$T$1:$T$26
Name PLAYERS_ECU: 'AWARDS_DATA'!$U$1:$U$26
Name PLAYERS_NED: 'AWARDS_DATA'!$V$1:$V$26
Name PLAYERS_JPN: 'AWARDS_DATA'!$W$1:$W$26
Name PLAYERS_TUN: 'AWARDS_DATA'!$X$1:$X$26
Name PLAYERS_SWE: 'AWARDS_DATA'!$Y$1:$Y$26
Name PLAYERS_BEL: 'AWARDS_DATA'!$Z$1:$Z$26
Name PLAYERS_EGY: 'AWARDS_DATA'!$AA$1:$AA$26
Name PLAYERS_IRN: 'AWARDS_DATA'!$AB$1:$AB$26
Name PLAYERS_NZL: 'AWARDS_DATA'!$AC$1:$AC$26
Name PLAYERS_ESP: 'AWARDS_DATA'!$AD$1:$AD$26
Name PLAYERS_URU: 'AWARDS_DATA'!$AE$1:$AE$26
Name PLAYERS_KSA: 'AWARDS_DATA'!$AF$1:$AF$26
Name PLAYERS_CPV: 'AWARDS_DATA'!$AG$1:$AG$26
Name PLAYERS_FRA: 'AWARDS_DATA'!$AH$1:$AH$26
Name PLAYERS_SEN: 'AWARDS_DATA'!$AI$1:$AI$26
Name PLAYERS_NOR: 'AWARDS_DATA'!$AJ$1:$AJ$26
Name PLAYERS_IRQ: 'AWARDS_DATA'!$AK$1:$AK$26
Name PLAYERS_ARG: 'AWARDS_DATA'!$AL$1:$AL$26
Name PLAYERS_AUT: 'AWARDS_DATA'!$AM$1:$AM$26
Name PLAYERS_ALG: 'AWARDS_DATA'!$AN$1:$AN$26
Name PLAYERS_JOR: 'AWARDS_DATA'!$AO$1:$AO$26
Name PLAYERS_POR: 'AWARDS_DATA'!$AP$1:$AP$26
Name PLAYERS_COL: 'AWARDS_DATA'!$AQ$1:$AQ$26
Name PLAYERS_UZB: 'AWARDS_DATA'!$AR$1:$AR$26
Name PLAYERS_COD: 'AWARDS_DATA'!$AS$1:$AS$26
Name PLAYERS_ENG: 'AWARDS_DATA'!$AT$1:$AT$26
Name PLAYERS_CRO: 'AWARDS_DATA'!$AU$1:$AU$26
Name PLAYERS_GHA: 'AWARDS_DATA'!$AV$1:$AV$26
Name PLAYERS_PAN: 'AWARDS_DATA'!$AW$1:$AW$26

Sheet Fase de Grupos
B2: GRUPO A | I2: =COUNTA($G$4:$G$9)&"/6" | M2: GRUPO B | T2: =COUNTA($R$4:$R$9)&"/6" | X2: GRUPO C | AE2: =COUNTA($AC$4:$AC$9)&"/6"
B3: ID | C3: Jornada | D3: Fecha | E3: Local | G3: GF | H3: - | I3: GC | K3: Visitante | M3: ID | N3: Jornada | O3: Fecha | P3: Local | R3: GF | S3: - | T3: GC | V3: Visitante | X3: ID | Y3: Jornada | Z3: Fecha | AA3: Local | AC3: GF | AD3: - | AE3: GC | AG3: Visitante
B4: M1 | C4: 1 | D4: 11/06 | E4: México | G4: 2 | H4: – | I4: 0 | K4: Sudáfrica | M4: M3 | N4: 1 | O4: 12/06 | P4: Canadá | S4: – | V4: Bosnia y Herz. | X4: M5 | Y4: 1 | Z4: 14/06 | AA4: Haití | AD4: – | AG4: Escocia
B5: M2 | C5: 1 | D5: 12/06 | E5: Corea del Sur | G5: 2 | H5: – | I5: 1 | K5: República Checa | M5: M8 | N5: 1 | O5: 13/06 | P5: Catar | S5: – | V5: Suiza | X5: M7 | Y5: 1 | Z5: 14/06 | AA5: Brasil | AD5: – | AG5: Marruecos
B6: M25 | C6: 2 | D6: 18/06 | E6: República Checa | H6: – | K6: Sudáfrica | M6: M26 | N6: 2 | O6: 18/06 | P6: Suiza | S6: – | V6: Bosnia y Herz. | X6: M29 | Y6: 2 | Z6: 20/06 | AA6: Brasil | AD6: – | AG6: Haití
B7: M28 | C7: 2 | D7: 19/06 | E7: México | H7: – | K7: Corea del Sur | M7: M27 | N7: 2 | O7: 19/06 | P7: Canadá | S7: – | V7: Catar | X7: M30 | Y7: 2 | Z7: 20/06 | AA7: Escocia | AD7: – | AG7: Marruecos
B8: M53 | C8: 3 | D8: 25/06 | E8: República Checa | H8: – | K8: México | M8: M51 | N8: 3 | O8: 24/06 | P8: Suiza | S8: – | V8: Canadá | X8: M49 | Y8: 3 | Z8: 25/06 | AA8: Escocia | AD8: – | AG8: Brasil
B9: M54 | C9: 3 | D9: 25/06 | E9: Sudáfrica | H9: – | K9: Corea del Sur | M9: M52 | N9: 3 | O9: 24/06 | P9: Bosnia y Herz. | S9: – | V9: Catar | X9: M50 | Y9: 3 | Z9: 25/06 | AA9: Marruecos | AD9: – | AG9: Haití
B10: CLASIFICACIÓN | M10: CLASIFICACIÓN | X10: CLASIFICACIÓN
B11: Pos | C11: Equipo | E11: PJ | F11: G | G11: E | H11: P | I11: GF | J11: GC | K11: PTS | M11: Pos | N11: Equipo | P11: PJ | Q11: G | R11: E | S11: P | T11: GF | U11: GC | V11: PTS | X11: Pos | Y11: Equipo | AA11: PJ | AB11: G | AC11: E | AD11: P | AE11: GF | AF11: GC | AG11: PTS
B12: 1 | C12: =INDEX(CALC!$B$2:$B$5,MATCH(LARGE(CALC!$K$2:$K$5,1),CALC!$K$2:$K$5,0)) | E12: =INDEX(CALC!$C$2:$C$5,MATCH(LARGE(CALC!$K$2:$K$5,1),CALC!$K$2:$K$5,0)) | F12: =INDEX(CALC!$D$2:$D$5,MATCH(LARGE(CALC!$K$2:$K$5,1),CALC!$K$2:$K$5,0)) | G12: =INDEX(CALC!$E$2:$E$5,MATCH(LARGE(CALC!$K$2:$K$5,1),CALC!$K$2:$K$5,0)) | H12: =INDEX(CALC!$F$2:$F$5,MATCH(LARGE(CALC!$K$2:$K$5,1),CALC!$K$2:$K$5,0)) | I12: =INDEX(CALC!$G$2:$G$5,MATCH(LARGE(CALC!$K$2:$K$5,1),CALC!$K$2:$K$5,0)) | J12: =INDEX(CALC!$H$2:$H$5,MATCH(LARGE(CALC!$K$2:$K$5,1),CALC!$K$2:$K$5,0)) | K12: =INDEX(CALC!$J$2:$J$5,MATCH(LARGE(CALC!$K$2:$K$5,1),CALC!$K$2:$K$5,0)) | M12: 1 | N12: =INDEX(CALC!$B$6:$B$9,MATCH(LARGE(CALC!$K$6:$K$9,1),CALC!$K$6:$K$9,0)) | P12: =INDEX(CALC!$C$6:$C$9,MATCH(LARGE(CALC!$K$6:$K$9,1),CALC!$K$6:$K$9,0)) | Q12: =INDEX(CALC!$D$6:$D$9,MATCH(LARGE(CALC!$K$6:$K$9,1),CALC!$K$6:$K$9,0)) | R12: =INDEX(CALC!$E$6:$E$9,MATCH(LARGE(CALC!$K$6:$K$9,1),CALC!$K$6:$K$9,0)) | S12: =INDEX(CALC!$F$6:$F$9,MATCH(LARGE(CALC!$K$6:$K$9,1),CALC!$K$6:$K$9,0)) | T12: =INDEX(CALC!$G$6:$G$9,MATCH(LARGE(CALC!$K$6:$K$9,1),CALC!$K$6:$K$9,0)) | U12: =INDEX(CALC!$H$6:$H$9,MATCH(LARGE(CALC!$K$6:$K$9,1),CALC!$K$6:$K$9,0)) | V12: =INDEX(CALC!$J$6:$J$9,MATCH(LARGE(CALC!$K$6:$K$9,1),CALC!$K$6:$K$9,0)) | X12: 1 | Y12: =INDEX(CALC!$B$10:$B$13,MATCH(LARGE(CALC!$K$10:$K$13,1),CALC!$K$10:$K$13,0)) | AA12: =INDEX(CALC!$C$10:$C$13,MATCH(LARGE(CALC!$K$10:$K$13,1),CALC!$K$10:$K$13,0)) | AB12: =INDEX(CALC!$D$10:$D$13,MATCH(LARGE(CALC!$K$10:$K$13,1),CALC!$K$10:$K$13,0)) | AC12: =INDEX(CALC!$E$10:$E$13,MATCH(LARGE(CALC!$K$10:$K$13,1),CALC!$K$10:$K$13,0)) | AD12: =INDEX(CALC!$F$10:$F$13,MATCH(LARGE(CALC!$K$10:$K$13,1),CALC!$K$10:$K$13,0)) | AE12: =INDEX(CALC!$G$10:$G$13,MATCH(LARGE(CALC!$K$10:$K$13,1),CALC!$K$10:$K$13,0)) | AF12: =INDEX(CALC!$H$10:$H$13,MATCH(LARGE(CALC!$K$10:$K$13,1),CALC!$K$10:$K$13,0)) | AG12: =INDEX(CALC!$J$10:$J$13,MATCH(LARGE(CALC!$K$10:$K$13,1),CALC!$K$10:$K$13,0))
B13: 2 | C13: =INDEX(CALC!$B$2:$B$5,MATCH(LARGE(CALC!$K$2:$K$5,2),CALC!$K$2:$K$5,0)) | E13: =INDEX(CALC!$C$2:$C$5,MATCH(LARGE(CALC!$K$2:$K$5,2),CALC!$K$2:$K$5,0)) | F13: =INDEX(CALC!$D$2:$D$5,MATCH(LARGE(CALC!$K$2:$K$5,2),CALC!$K$2:$K$5,0)) | G13: =INDEX(CALC!$E$2:$E$5,MATCH(LARGE(CALC!$K$2:$K$5,2),CALC!$K$2:$K$5,0)) | H13: =INDEX(CALC!$F$2:$F$5,MATCH(LARGE(CALC!$K$2:$K$5,2),CALC!$K$2:$K$5,0)) | I13: =INDEX(CALC!$G$2:$G$5,MATCH(LARGE(CALC!$K$2:$K$5,2),CALC!$K$2:$K$5,0)) | J13: =INDEX(CALC!$H$2:$H$5,MATCH(LARGE(CALC!$K$2:$K$5,2),CALC!$K$2:$K$5,0)) | K13: =INDEX(CALC!$J$2:$J$5,MATCH(LARGE(CALC!$K$2:$K$5,2),CALC!$K$2:$K$5,0)) | M13: 2 | N13: =INDEX(CALC!$B$6:$B$9,MATCH(LARGE(CALC!$K$6:$K$9,2),CALC!$K$6:$K$9,0)) | P13: =INDEX(CALC!$C$6:$C$9,MATCH(LARGE(CALC!$K$6:$K$9,2),CALC!$K$6:$K$9,0)) | Q13: =INDEX(CALC!$D$6:$D$9,MATCH(LARGE(CALC!$K$6:$K$9,2),CALC!$K$6:$K$9,0)) | R13: =INDEX(CALC!$E$6:$E$9,MATCH(LARGE(CALC!$K$6:$K$9,2),CALC!$K$6:$K$9,0)) | S13: =INDEX(CALC!$F$6:$F$9,MATCH(LARGE(CALC!$K$6:$K$9,2),CALC!$K$6:$K$9,0)) | T13: =INDEX(CALC!$G$6:$G$9,MATCH(LARGE(CALC!$K$6:$K$9,2),CALC!$K$6:$K$9,0)) | U13: =INDEX(CALC!$H$6:$H$9,MATCH(LARGE(CALC!$K$6:$K$9,2),CALC!$K$6:$K$9,0)) | V13: =INDEX(CALC!$J$6:$J$9,MATCH(LARGE(CALC!$K$6:$K$9,2),CALC!$K$6:$K$9,0)) | X13: 2 | Y13: =INDEX(CALC!$B$10:$B$13,MATCH(LARGE(CALC!$K$10:$K$13,2),CALC!$K$10:$K$13,0)) | AA13: =INDEX(CALC!$C$10:$C$13,MATCH(LARGE(CALC!$K$10:$K$13,2),CALC!$K$10:$K$13,0)) | AB13: =INDEX(CALC!$D$10:$D$13,MATCH(LARGE(CALC!$K$10:$K$13,2),CALC!$K$10:$K$13,0)) | AC13: =INDEX(CALC!$E$10:$E$13,MATCH(LARGE(CALC!$K$10:$K$13,2),CALC!$K$10:$K$13,0)) | AD13: =INDEX(CALC!$F$10:$F$13,MATCH(LARGE(CALC!$K$10:$K$13,2),CALC!$K$10:$K$13,0)) | AE13: =INDEX(CALC!$G$10:$G$13,MATCH(LARGE(CALC!$K$10:$K$13,2),CALC!$K$10:$K$13,0)) | AF13: =INDEX(CALC!$H$10:$H$13,MATCH(LARGE(CALC!$K$10:$K$13,2),CALC!$K$10:$K$13,0)) | AG13: =INDEX(CALC!$J$10:$J$13,MATCH(LARGE(CALC!$K$10:$K$13,2),CALC!$K$10:$K$13,0))
B14: 3 | C14: =INDEX(CALC!$B$2:$B$5,MATCH(LARGE(CALC!$K$2:$K$5,3),CALC!$K$2:$K$5,0)) | E14: =INDEX(CALC!$C$2:$C$5,MATCH(LARGE(CALC!$K$2:$K$5,3),CALC!$K$2:$K$5,0)) | F14: =INDEX(CALC!$D$2:$D$5,MATCH(LARGE(CALC!$K$2:$K$5,3),CALC!$K$2:$K$5,0)) | G14: =INDEX(CALC!$E$2:$E$5,MATCH(LARGE(CALC!$K$2:$K$5,3),CALC!$K$2:$K$5,0)) | H14: =INDEX(CALC!$F$2:$F$5,MATCH(LARGE(CALC!$K$2:$K$5,3),CALC!$K$2:$K$5,0)) | I14: =INDEX(CALC!$G$2:$G$5,MATCH(LARGE(CALC!$K$2:$K$5,3),CALC!$K$2:$K$5,0)) | J14: =INDEX(CALC!$H$2:$H$5,MATCH(LARGE(CALC!$K$2:$K$5,3),CALC!$K$2:$K$5,0)) | K14: =INDEX(CALC!$J$2:$J$5,MATCH(LARGE(CALC!$K$2:$K$5,3),CALC!$K$2:$K$5,0)) | M14: 3 | N14: =INDEX(CALC!$B$6:$B$9,MATCH(LARGE(CALC!$K$6:$K$9,3),CALC!$K$6:$K$9,0)) | P14: =INDEX(CALC!$C$6:$C$9,MATCH(LARGE(CALC!$K$6:$K$9,3),CALC!$K$6:$K$9,0)) | Q14: =INDEX(CALC!$D$6:$D$9,MATCH(LARGE(CALC!$K$6:$K$9,3),CALC!$K$6:$K$9,0)) | R14: =INDEX(CALC!$E$6:$E$9,MATCH(LARGE(CALC!$K$6:$K$9,3),CALC!$K$6:$K$9,0)) | S14: =INDEX(CALC!$F$6:$F$9,MATCH(LARGE(CALC!$K$6:$K$9,3),CALC!$K$6:$K$9,0)) | T14: =INDEX(CALC!$G$6:$G$9,MATCH(LARGE(CALC!$K$6:$K$9,3),CALC!$K$6:$K$9,0)) | U14: =INDEX(CALC!$H$6:$H$9,MATCH(LARGE(CALC!$K$6:$K$9,3),CALC!$K$6:$K$9,0)) | V14: =INDEX(CALC!$J$6:$J$9,MATCH(LARGE(CALC!$K$6:$K$9,3),CALC!$K$6:$K$9,0)) | X14: 3 | Y14: =INDEX(CALC!$B$10:$B$13,MATCH(LARGE(CALC!$K$10:$K$13,3),CALC!$K$10:$K$13,0)) | AA14: =INDEX(CALC!$C$10:$C$13,MATCH(LARGE(CALC!$K$10:$K$13,3),CALC!$K$10:$K$13,0)) | AB14: =INDEX(CALC!$D$10:$D$13,MATCH(LARGE(CALC!$K$10:$K$13,3),CALC!$K$10:$K$13,0)) | AC14: =INDEX(CALC!$E$10:$E$13,MATCH(LARGE(CALC!$K$10:$K$13,3),CALC!$K$10:$K$13,0)) | AD14: =INDEX(CALC!$F$10:$F$13,MATCH(LARGE(CALC!$K$10:$K$13,3),CALC!$K$10:$K$13,0)) | AE14: =INDEX(CALC!$G$10:$G$13,MATCH(LARGE(CALC!$K$10:$K$13,3),CALC!$K$10:$K$13,0)) | AF14: =INDEX(CALC!$H$10:$H$13,MATCH(LARGE(CALC!$K$10:$K$13,3),CALC!$K$10:$K$13,0)) | AG14: =INDEX(CALC!$J$10:$J$13,MATCH(LARGE(CALC!$K$10:$K$13,3),CALC!$K$10:$K$13,0))
B15: 4 | C15: =INDEX(CALC!$B$2:$B$5,MATCH(LARGE(CALC!$K$2:$K$5,4),CALC!$K$2:$K$5,0)) | E15: =INDEX(CALC!$C$2:$C$5,MATCH(LARGE(CALC!$K$2:$K$5,4),CALC!$K$2:$K$5,0)) | F15: =INDEX(CALC!$D$2:$D$5,MATCH(LARGE(CALC!$K$2:$K$5,4),CALC!$K$2:$K$5,0)) | G15: =INDEX(CALC!$E$2:$E$5,MATCH(LARGE(CALC!$K$2:$K$5,4),CALC!$K$2:$K$5,0)) | H15: =INDEX(CALC!$F$2:$F$5,MATCH(LARGE(CALC!$K$2:$K$5,4),CALC!$K$2:$K$5,0)) | I15: =INDEX(CALC!$G$2:$G$5,MATCH(LARGE(CALC!$K$2:$K$5,4),CALC!$K$2:$K$5,0)) | J15: =INDEX(CALC!$H$2:$H$5,MATCH(LARGE(CALC!$K$2:$K$5,4),CALC!$K$2:$K$5,0)) | K15: =INDEX(CALC!$J$2:$J$5,MATCH(LARGE(CALC!$K$2:$K$5,4),CALC!$K$2:$K$5,0)) | M15: 4 | N15: =INDEX(CALC!$B$6:$B$9,MATCH(LARGE(CALC!$K$6:$K$9,4),CALC!$K$6:$K$9,0)) | P15: =INDEX(CALC!$C$6:$C$9,MATCH(LARGE(CALC!$K$6:$K$9,4),CALC!$K$6:$K$9,0)) | Q15: =INDEX(CALC!$D$6:$D$9,MATCH(LARGE(CALC!$K$6:$K$9,4),CALC!$K$6:$K$9,0)) | R15: =INDEX(CALC!$E$6:$E$9,MATCH(LARGE(CALC!$K$6:$K$9,4),CALC!$K$6:$K$9,0)) | S15: =INDEX(CALC!$F$6:$F$9,MATCH(LARGE(CALC!$K$6:$K$9,4),CALC!$K$6:$K$9,0)) | T15: =INDEX(CALC!$G$6:$G$9,MATCH(LARGE(CALC!$K$6:$K$9,4),CALC!$K$6:$K$9,0)) | U15: =INDEX(CALC!$H$6:$H$9,MATCH(LARGE(CALC!$K$6:$K$9,4),CALC!$K$6:$K$9,0)) | V15: =INDEX(CALC!$J$6:$J$9,MATCH(LARGE(CALC!$K$6:$K$9,4),CALC!$K$6:$K$9,0)) | X15: 4 | Y15: =INDEX(CALC!$B$10:$B$13,MATCH(LARGE(CALC!$K$10:$K$13,4),CALC!$K$10:$K$13,0)) | AA15: =INDEX(CALC!$C$10:$C$13,MATCH(LARGE(CALC!$K$10:$K$13,4),CALC!$K$10:$K$13,0)) | AB15: =INDEX(CALC!$D$10:$D$13,MATCH(LARGE(CALC!$K$10:$K$13,4),CALC!$K$10:$K$13,0)) | AC15: =INDEX(CALC!$E$10:$E$13,MATCH(LARGE(CALC!$K$10:$K$13,4),CALC!$K$10:$K$13,0)) | AD15: =INDEX(CALC!$F$10:$F$13,MATCH(LARGE(CALC!$K$10:$K$13,4),CALC!$K$10:$K$13,0)) | AE15: =INDEX(CALC!$G$10:$G$13,MATCH(LARGE(CALC!$K$10:$K$13,4),CALC!$K$10:$K$13,0)) | AF15: =INDEX(CALC!$H$10:$H$13,MATCH(LARGE(CALC!$K$10:$K$13,4),CALC!$K$10:$K$13,0)) | AG15: =INDEX(CALC!$J$10:$J$13,MATCH(LARGE(CALC!$K$10:$K$13,4),CALC!$K$10:$K$13,0))
B19: GRUPO D | I19: =COUNTA($G$21:$G$26)&"/6" | M19: GRUPO E | T19: =COUNTA($R$21:$R$26)&"/6" | X19: GRUPO F | AE19: =COUNTA($AC$21:$AC$26)&"/6"
B20: ID | C20: Jornada | D20: Fecha | E20: Local | G20: GF | H20: - | I20: GC | K20: Visitante | M20: ID | N20: Jornada | O20: Fecha | P20: Local | R20: GF | S20: - | T20: GC | V20: Visitante | X20: ID | Y20: Jornada | Z20: Fecha | AA20: Local | AC20: GF | AD20: - | AE20: GC | AG20: Visitante
B21: M4 | C21: 1 | D21: 13/06 | E21: Estados Unidos | H21: – | K21: Paraguay | M21: M9 | N21: 1 | O21: 15/06 | P21: Costa de Marfil | S21: – | V21: Ecuador | X21: M11 | Y21: 1 | Z21: 14/06 | AA21: Países Bajos | AD21: – | AG21: Japón
B22: M6 | C22: 1 | D22: 14/06 | E22: Australia | H22: – | K22: Turquía | M22: M10 | N22: 1 | O22: 14/06 | P22: Alemania | S22: – | V22: Curazao | X22: M12 | Y22: 1 | Z22: 15/06 | AA22: Suecia | AD22: – | AG22: Túnez
B23: M31 | C23: 2 | D23: 20/06 | E23: Turquía | H23: – | K23: Paraguay | M23: M33 | N23: 2 | O23: 20/06 | P23: Alemania | S23: – | V23: Costa de Marfil | X23: M35 | Y23: 2 | Z23: 20/06 | AA23: Países Bajos | AD23: – | AG23: Suecia
B24: M32 | C24: 2 | D24: 19/06 | E24: Estados Unidos | H24: – | K24: Australia | M24: M34 | N24: 2 | O24: 21/06 | P24: Ecuador | S24: – | V24: Curazao | X24: M36 | Y24: 2 | Z24: 21/06 | AA24: Túnez | AD24: – | AG24: Japón
B25: M59 | C25: 3 | D25: 26/06 | E25: Turquía | H25: – | K25: Estados Unidos | M25: M55 | N25: 3 | O25: 25/06 | P25: Curazao | S25: – | V25: Costa de Marfil | X25: M57 | Y25: 3 | Z25: 26/06 | AA25: Japón | AD25: – | AG25: Suecia
B26: M60 | C26: 3 | D26: 26/06 | E26: Paraguay | H26: – | K26: Australia | M26: M56 | N26: 3 | O26: 25/06 | P26: Ecuador | S26: – | V26: Alemania | X26: M58 | Y26: 3 | Z26: 26/06 | AA26: Túnez | AD26: – | AG26: Países Bajos
B27: CLASIFICACIÓN | M27: CLASIFICACIÓN | X27: CLASIFICACIÓN
B28: Pos | C28: Equipo | E28: PJ | F28: G | G28: E | H28: P | I28: GF | J28: GC | K28: PTS | M28: Pos | N28: Equipo | P28: PJ | Q28: G | R28: E | S28: P | T28: GF | U28: GC | V28: PTS | X28: Pos | Y28: Equipo | AA28: PJ | AB28: G | AC28: E | AD28: P | AE28: GF | AF28: GC | AG28: PTS
B29: 1 | C29: =INDEX(CALC!$B$14:$B$17,MATCH(LARGE(CALC!$K$14:$K$17,1),CALC!$K$14:$K$17,0)) | E29: =INDEX(CALC!$C$14:$C$17,MATCH(LARGE(CALC!$K$14:$K$17,1),CALC!$K$14:$K$17,0)) | F29: =INDEX(CALC!$D$14:$D$17,MATCH(LARGE(CALC!$K$14:$K$17,1),CALC!$K$14:$K$17,0)) | G29: =INDEX(CALC!$E$14:$E$17,MATCH(LARGE(CALC!$K$14:$K$17,1),CALC!$K$14:$K$17,0)) | H29: =INDEX(CALC!$F$14:$F$17,MATCH(LARGE(CALC!$K$14:$K$17,1),CALC!$K$14:$K$17,0)) | I29: =INDEX(CALC!$G$14:$G$17,MATCH(LARGE(CALC!$K$14:$K$17,1),CALC!$K$14:$K$17,0)) | J29: =INDEX(CALC!$H$14:$H$17,MATCH(LARGE(CALC!$K$14:$K$17,1),CALC!$K$14:$K$17,0)) | K29: =INDEX(CALC!$J$14:$J$17,MATCH(LARGE(CALC!$K$14:$K$17,1),CALC!$K$14:$K$17,0)) | M29: 1 | N29: =INDEX(CALC!$B$18:$B$21,MATCH(LARGE(CALC!$K$18:$K$21,1),CALC!$K$18:$K$21,0)) | P29: =INDEX(CALC!$C$18:$C$21,MATCH(LARGE(CALC!$K$18:$K$21,1),CALC!$K$18:$K$21,0)) | Q29: =INDEX(CALC!$D$18:$D$21,MATCH(LARGE(CALC!$K$18:$K$21,1),CALC!$K$18:$K$21,0)) | R29: =INDEX(CALC!$E$18:$E$21,MATCH(LARGE(CALC!$K$18:$K$21,1),CALC!$K$18:$K$21,0)) | S29: =INDEX(CALC!$F$18:$F$21,MATCH(LARGE(CALC!$K$18:$K$21,1),CALC!$K$18:$K$21,0)) | T29: =INDEX(CALC!$G$18:$G$21,MATCH(LARGE(CALC!$K$18:$K$21,1),CALC!$K$18:$K$21,0)) | U29: =INDEX(CALC!$H$18:$H$21,MATCH(LARGE(CALC!$K$18:$K$21,1),CALC!$K$18:$K$21,0)) | V29: =INDEX(CALC!$J$18:$J$21,MATCH(LARGE(CALC!$K$18:$K$21,1),CALC!$K$18:$K$21,0)) | X29: 1 | Y29: =INDEX(CALC!$B$22:$B$25,MATCH(LARGE(CALC!$K$22:$K$25,1),CALC!$K$22:$K$25,0)) | AA29: =INDEX(CALC!$C$22:$C$25,MATCH(LARGE(CALC!$K$22:$K$25,1),CALC!$K$22:$K$25,0)) | AB29: =INDEX(CALC!$D$22:$D$25,MATCH(LARGE(CALC!$K$22:$K$25,1),CALC!$K$22:$K$25,0)) | AC29: =INDEX(CALC!$E$22:$E$25,MATCH(LARGE(CALC!$K$22:$K$25,1),CALC!$K$22:$K$25,0)) | AD29: =INDEX(CALC!$F$22:$F$25,MATCH(LARGE(CALC!$K$22:$K$25,1),CALC!$K$22:$K$25,0)) | AE29: =INDEX(CALC!$G$22:$G$25,MATCH(LARGE(CALC!$K$22:$K$25,1),CALC!$K$22:$K$25,0)) | AF29: =INDEX(CALC!$H$22:$H$25,MATCH(LARGE(CALC!$K$22:$K$25,1),CALC!$K$22:$K$25,0)) | AG29: =INDEX(CALC!$J$22:$J$25,MATCH(LARGE(CALC!$K$22:$K$25,1),CALC!$K$22:$K$25,0))
B30: 2 | C30: =INDEX(CALC!$B$14:$B$17,MATCH(LARGE(CALC!$K$14:$K$17,2),CALC!$K$14:$K$17,0)) | E30: =INDEX(CALC!$C$14:$C$17,MATCH(LARGE(CALC!$K$14:$K$17,2),CALC!$K$14:$K$17,0)) | F30: =INDEX(CALC!$D$14:$D$17,MATCH(LARGE(CALC!$K$14:$K$17,2),CALC!$K$14:$K$17,0)) | G30: =INDEX(CALC!$E$14:$E$17,MATCH(LARGE(CALC!$K$14:$K$17,2),CALC!$K$14:$K$17,0)) | H30: =INDEX(CALC!$F$14:$F$17,MATCH(LARGE(CALC!$K$14:$K$17,2),CALC!$K$14:$K$17,0)) | I30: =INDEX(CALC!$G$14:$G$17,MATCH(LARGE(CALC!$K$14:$K$17,2),CALC!$K$14:$K$17,0)) | J30: =INDEX(CALC!$H$14:$H$17,MATCH(LARGE(CALC!$K$14:$K$17,2),CALC!$K$14:$K$17,0)) | K30: =INDEX(CALC!$J$14:$J$17,MATCH(LARGE(CALC!$K$14:$K$17,2),CALC!$K$14:$K$17,0)) | M30: 2 | N30: =INDEX(CALC!$B$18:$B$21,MATCH(LARGE(CALC!$K$18:$K$21,2),CALC!$K$18:$K$21,0)) | P30: =INDEX(CALC!$C$18:$C$21,MATCH(LARGE(CALC!$K$18:$K$21,2),CALC!$K$18:$K$21,0)) | Q30: =INDEX(CALC!$D$18:$D$21,MATCH(LARGE(CALC!$K$18:$K$21,2),CALC!$K$18:$K$21,0)) | R30: =INDEX(CALC!$E$18:$E$21,MATCH(LARGE(CALC!$K$18:$K$21,2),CALC!$K$18:$K$21,0)) | S30: =INDEX(CALC!$F$18:$F$21,MATCH(LARGE(CALC!$K$18:$K$21,2),CALC!$K$18:$K$21,0)) | T30: =INDEX(CALC!$G$18:$G$21,MATCH(LARGE(CALC!$K$18:$K$21,2),CALC!$K$18:$K$21,0)) | U30: =INDEX(CALC!$H$18:$H$21,MATCH(LARGE(CALC!$K$18:$K$21,2),CALC!$K$18:$K$21,0)) | V30: =INDEX(CALC!$J$18:$J$21,MATCH(LARGE(CALC!$K$18:$K$21,2),CALC!$K$18:$K$21,0)) | X30: 2 | Y30: =INDEX(CALC!$B$22:$B$25,MATCH(LARGE(CALC!$K$22:$K$25,2),CALC!$K$22:$K$25,0)) | AA30: =INDEX(CALC!$C$22:$C$25,MATCH(LARGE(CALC!$K$22:$K$25,2),CALC!$K$22:$K$25,0)) | AB30: =INDEX(CALC!$D$22:$D$25,MATCH(LARGE(CALC!$K$22:$K$25,2),CALC!$K$22:$K$25,0)) | AC30: =INDEX(CALC!$E$22:$E$25,MATCH(LARGE(CALC!$K$22:$K$25,2),CALC!$K$22:$K$25,0)) | AD30: =INDEX(CALC!$F$22:$F$25,MATCH(LARGE(CALC!$K$22:$K$25,2),CALC!$K$22:$K$25,0)) | AE30: =INDEX(CALC!$G$22:$G$25,MATCH(LARGE(CALC!$K$22:$K$25,2),CALC!$K$22:$K$25,0)) | AF30: =INDEX(CALC!$H$22:$H$25,MATCH(LARGE(CALC!$K$22:$K$25,2),CALC!$K$22:$K$25,0)) | AG30: =INDEX(CALC!$J$22:$J$25,MATCH(LARGE(CALC!$K$22:$K$25,2),CALC!$K$22:$K$25,0))
B31: 3 | C31: =INDEX(CALC!$B$14:$B$17,MATCH(LARGE(CALC!$K$14:$K$17,3),CALC!$K$14:$K$17,0)) | E31: =INDEX(CALC!$C$14:$C$17,MATCH(LARGE(CALC!$K$14:$K$17,3),CALC!$K$14:$K$17,0)) | F31: =INDEX(CALC!$D$14:$D$17,MATCH(LARGE(CALC!$K$14:$K$17,3),CALC!$K$14:$K$17,0)) | G31: =INDEX(CALC!$E$14:$E$17,MATCH(LARGE(CALC!$K$14:$K$17,3),CALC!$K$14:$K$17,0)) | H31: =INDEX(CALC!$F$14:$F$17,MATCH(LARGE(CALC!$K$14:$K$17,3),CALC!$K$14:$K$17,0)) | I31: =INDEX(CALC!$G$14:$G$17,MATCH(LARGE(CALC!$K$14:$K$17,3),CALC!$K$14:$K$17,0)) | J31: =INDEX(CALC!$H$14:$H$17,MATCH(LARGE(CALC!$K$14:$K$17,3),CALC!$K$14:$K$17,0)) | K31: =INDEX(CALC!$J$14:$J$17,MATCH(LARGE(CALC!$K$14:$K$17,3),CALC!$K$14:$K$17,0)) | M31: 3 | N31: =INDEX(CALC!$B$18:$B$21,MATCH(LARGE(CALC!$K$18:$K$21,3),CALC!$K$18:$K$21,0)) | P31: =INDEX(CALC!$C$18:$C$21,MATCH(LARGE(CALC!$K$18:$K$21,3),CALC!$K$18:$K$21,0)) | Q31: =INDEX(CALC!$D$18:$D$21,MATCH(LARGE(CALC!$K$18:$K$21,3),CALC!$K$18:$K$21,0)) | R31: =INDEX(CALC!$E$18:$E$21,MATCH(LARGE(CALC!$K$18:$K$21,3),CALC!$K$18:$K$21,0)) | S31: =INDEX(CALC!$F$18:$F$21,MATCH(LARGE(CALC!$K$18:$K$21,3),CALC!$K$18:$K$21,0)) | T31: =INDEX(CALC!$G$18:$G$21,MATCH(LARGE(CALC!$K$18:$K$21,3),CALC!$K$18:$K$21,0)) | U31: =INDEX(CALC!$H$18:$H$21,MATCH(LARGE(CALC!$K$18:$K$21,3),CALC!$K$18:$K$21,0)) | V31: =INDEX(CALC!$J$18:$J$21,MATCH(LARGE(CALC!$K$18:$K$21,3),CALC!$K$18:$K$21,0)) | X31: 3 | Y31: =INDEX(CALC!$B$22:$B$25,MATCH(LARGE(CALC!$K$22:$K$25,3),CALC!$K$22:$K$25,0)) | AA31: =INDEX(CALC!$C$22:$C$25,MATCH(LARGE(CALC!$K$22:$K$25,3),CALC!$K$22:$K$25,0)) | AB31: =INDEX(CALC!$D$22:$D$25,MATCH(LARGE(CALC!$K$22:$K$25,3),CALC!$K$22:$K$25,0)) | AC31: =INDEX(CALC!$E$22:$E$25,MATCH(LARGE(CALC!$K$22:$K$25,3),CALC!$K$22:$K$25,0)) | AD31: =INDEX(CALC!$F$22:$F$25,MATCH(LARGE(CALC!$K$22:$K$25,3),CALC!$K$22:$K$25,0)) | AE31: =INDEX(CALC!$G$22:$G$25,MATCH(LARGE(CALC!$K$22:$K$25,3),CALC!$K$22:$K$25,0)) | AF31: =INDEX(CALC!$H$22:$H$25,MATCH(LARGE(CALC!$K$22:$K$25,3),CALC!$K$22:$K$25,0)) | AG31: =INDEX(CALC!$J$22:$J$25,MATCH(LARGE(CALC!$K$22:$K$25,3),CALC!$K$22:$K$25,0))
B32: 4 | C32: =INDEX(CALC!$B$14:$B$17,MATCH(LARGE(CALC!$K$14:$K$17,4),CALC!$K$14:$K$17,0)) | E32: =INDEX(CALC!$C$14:$C$17,MATCH(LARGE(CALC!$K$14:$K$17,4),CALC!$K$14:$K$17,0)) | F32: =INDEX(CALC!$D$14:$D$17,MATCH(LARGE(CALC!$K$14:$K$17,4),CALC!$K$14:$K$17,0)) | G32: =INDEX(CALC!$E$14:$E$17,MATCH(LARGE(CALC!$K$14:$K$17,4),CALC!$K$14:$K$17,0)) | H32: =INDEX(CALC!$F$14:$F$17,MATCH(LARGE(CALC!$K$14:$K$17,4),CALC!$K$14:$K$17,0)) | I32: =INDEX(CALC!$G$14:$G$17,MATCH(LARGE(CALC!$K$14:$K$17,4),CALC!$K$14:$K$17,0)) | J32: =INDEX(CALC!$H$14:$H$17,MATCH(LARGE(CALC!$K$14:$K$17,4),CALC!$K$14:$K$17,0)) | K32: =INDEX(CALC!$J$14:$J$17,MATCH(LARGE(CALC!$K$14:$K$17,4),CALC!$K$14:$K$17,0)) | M32: 4 | N32: =INDEX(CALC!$B$18:$B$21,MATCH(LARGE(CALC!$K$18:$K$21,4),CALC!$K$18:$K$21,0)) | P32: =INDEX(CALC!$C$18:$C$21,MATCH(LARGE(CALC!$K$18:$K$21,4),CALC!$K$18:$K$21,0)) | Q32: =INDEX(CALC!$D$18:$D$21,MATCH(LARGE(CALC!$K$18:$K$21,4),CALC!$K$18:$K$21,0)) | R32: =INDEX(CALC!$E$18:$E$21,MATCH(LARGE(CALC!$K$18:$K$21,4),CALC!$K$18:$K$21,0)) | S32: =INDEX(CALC!$F$18:$F$21,MATCH(LARGE(CALC!$K$18:$K$21,4),CALC!$K$18:$K$21,0)) | T32: =INDEX(CALC!$G$18:$G$21,MATCH(LARGE(CALC!$K$18:$K$21,4),CALC!$K$18:$K$21,0)) | U32: =INDEX(CALC!$H$18:$H$21,MATCH(LARGE(CALC!$K$18:$K$21,4),CALC!$K$18:$K$21,0)) | V32: =INDEX(CALC!$J$18:$J$21,MATCH(LARGE(CALC!$K$18:$K$21,4),CALC!$K$18:$K$21,0)) | X32: 4 | Y32: =INDEX(CALC!$B$22:$B$25,MATCH(LARGE(CALC!$K$22:$K$25,4),CALC!$K$22:$K$25,0)) | AA32: =INDEX(CALC!$C$22:$C$25,MATCH(LARGE(CALC!$K$22:$K$25,4),CALC!$K$22:$K$25,0)) | AB32: =INDEX(CALC!$D$22:$D$25,MATCH(LARGE(CALC!$K$22:$K$25,4),CALC!$K$22:$K$25,0)) | AC32: =INDEX(CALC!$E$22:$E$25,MATCH(LARGE(CALC!$K$22:$K$25,4),CALC!$K$22:$K$25,0)) | AD32: =INDEX(CALC!$F$22:$F$25,MATCH(LARGE(CALC!$K$22:$K$25,4),CALC!$K$22:$K$25,0)) | AE32: =INDEX(CALC!$G$22:$G$25,MATCH(LARGE(CALC!$K$22:$K$25,4),CALC!$K$22:$K$25,0)) | AF32: =INDEX(CALC!$H$22:$H$25,MATCH(LARGE(CALC!$K$22:$K$25,4),CALC!$K$22:$K$25,0)) | AG32: =INDEX(CALC!$J$22:$J$25,MATCH(LARGE(CALC!$K$22:$K$25,4),CALC!$K$22:$K$25,0))
B36: GRUPO G | I36: =COUNTA($G$38:$G$43)&"/6" | M36: GRUPO H | T36: =COUNTA($R$38:$R$43)&"/6" | X36: GRUPO I | AE36: =COUNTA($AC$38:$AC$43)&"/6"
B37: ID | C37: Jornada | D37: Fecha | E37: Local | G37: GF | H37: - | I37: GC | K37: Visitante | M37: ID | N37: Jornada | O37: Fecha | P37: Local | R37: GF | S37: - | T37: GC | V37: Visitante | X37: ID | Y37: Jornada | Z37: Fecha | AA37: Local | AC37: GF | AD37: - | AE37: GC | AG37: Visitante
B38: M15 | C38: 1 | D38: 16/06 | E38: Irán | H38: – | K38: Nueva Zelanda | M38: M13 | N38: 1 | O38: 16/06 | P38: Arabia Saudita | S38: – | V38: Uruguay | X38: M17 | Y38: 1 | Z38: 16/06 | AA38: Francia | AD38: – | AG38: Senegal
B39: M16 | C39: 1 | D39: 15/06 | E39: Bélgica | H39: – | K39: Egipto | M39: M14 | N39: 1 | O39: 15/06 | P39: España | S39: – | V39: Cabo Verde | X39: M18 | Y39: 1 | Z39: 17/06 | AA39: Irak | AD39: – | AG39: Noruega
B40: M39 | C40: 2 | D40: 21/06 | E40: Bélgica | H40: – | K40: Irán | M40: M37 | N40: 2 | O40: 22/06 | P40: Uruguay | S40: – | V40: Cabo Verde | X40: M41 | Y40: 2 | Z40: 23/06 | AA40: Noruega | AD40: – | AG40: Senegal
B41: M40 | C41: 2 | D41: 22/06 | E41: Nueva Zelanda | H41: – | K41: Egipto | M41: M38 | N41: 2 | O41: 21/06 | P41: España | S41: – | V41: Arabia Saudita | X41: M42 | Y41: 2 | Z41: 22/06 | AA41: Francia | AD41: – | AG41: Irak
B42: M63 | C42: 3 | D42: 27/06 | E42: Egipto | H42: – | K42: Irán | M42: M65 | N42: 3 | O42: 27/06 | P42: Cabo Verde | S42: – | V42: Arabia Saudita | X42: M61 | Y42: 3 | Z42: 26/06 | AA42: Noruega | AD42: – | AG42: Francia
B43: M64 | C43: 3 | D43: 27/06 | E43: Nueva Zelanda | H43: – | K43: Bélgica | M43: M66 | N43: 3 | O43: 27/06 | P43: Uruguay | S43: – | V43: España | X43: M62 | Y43: 3 | Z43: 26/06 | AA43: Senegal | AD43: – | AG43: Irak
B44: CLASIFICACIÓN | M44: CLASIFICACIÓN | X44: CLASIFICACIÓN
B45: Pos | C45: Equipo | E45: PJ | F45: G | G45: E | H45: P | I45: GF | J45: GC | K45: PTS | M45: Pos | N45: Equipo | P45: PJ | Q45: G | R45: E | S45: P | T45: GF | U45: GC | V45: PTS | X45: Pos | Y45: Equipo | AA45: PJ | AB45: G | AC45: E | AD45: P | AE45: GF | AF45: GC | AG45: PTS
B46: 1 | C46: =INDEX(CALC!$B$26:$B$29,MATCH(LARGE(CALC!$K$26:$K$29,1),CALC!$K$26:$K$29,0)) | E46: =INDEX(CALC!$C$26:$C$29,MATCH(LARGE(CALC!$K$26:$K$29,1),CALC!$K$26:$K$29,0)) | F46: =INDEX(CALC!$D$26:$D$29,MATCH(LARGE(CALC!$K$26:$K$29,1),CALC!$K$26:$K$29,0)) | G46: =INDEX(CALC!$E$26:$E$29,MATCH(LARGE(CALC!$K$26:$K$29,1),CALC!$K$26:$K$29,0)) | H46: =INDEX(CALC!$F$26:$F$29,MATCH(LARGE(CALC!$K$26:$K$29,1),CALC!$K$26:$K$29,0)) | I46: =INDEX(CALC!$G$26:$G$29,MATCH(LARGE(CALC!$K$26:$K$29,1),CALC!$K$26:$K$29,0)) | J46: =INDEX(CALC!$H$26:$H$29,MATCH(LARGE(CALC!$K$26:$K$29,1),CALC!$K$26:$K$29,0)) | K46: =INDEX(CALC!$J$26:$J$29,MATCH(LARGE(CALC!$K$26:$K$29,1),CALC!$K$26:$K$29,0)) | M46: 1 | N46: =INDEX(CALC!$B$30:$B$33,MATCH(LARGE(CALC!$K$30:$K$33,1),CALC!$K$30:$K$33,0)) | P46: =INDEX(CALC!$C$30:$C$33,MATCH(LARGE(CALC!$K$30:$K$33,1),CALC!$K$30:$K$33,0)) | Q46: =INDEX(CALC!$D$30:$D$33,MATCH(LARGE(CALC!$K$30:$K$33,1),CALC!$K$30:$K$33,0)) | R46: =INDEX(CALC!$E$30:$E$33,MATCH(LARGE(CALC!$K$30:$K$33,1),CALC!$K$30:$K$33,0)) | S46: =INDEX(CALC!$F$30:$F$33,MATCH(LARGE(CALC!$K$30:$K$33,1),CALC!$K$30:$K$33,0)) | T46: =INDEX(CALC!$G$30:$G$33,MATCH(LARGE(CALC!$K$30:$K$33,1),CALC!$K$30:$K$33,0)) | U46: =INDEX(CALC!$H$30:$H$33,MATCH(LARGE(CALC!$K$30:$K$33,1),CALC!$K$30:$K$33,0)) | V46: =INDEX(CALC!$J$30:$J$33,MATCH(LARGE(CALC!$K$30:$K$33,1),CALC!$K$30:$K$33,0)) | X46: 1 | Y46: =INDEX(CALC!$B$34:$B$37,MATCH(LARGE(CALC!$K$34:$K$37,1),CALC!$K$34:$K$37,0)) | AA46: =INDEX(CALC!$C$34:$C$37,MATCH(LARGE(CALC!$K$34:$K$37,1),CALC!$K$34:$K$37,0)) | AB46: =INDEX(CALC!$D$34:$D$37,MATCH(LARGE(CALC!$K$34:$K$37,1),CALC!$K$34:$K$37,0)) | AC46: =INDEX(CALC!$E$34:$E$37,MATCH(LARGE(CALC!$K$34:$K$37,1),CALC!$K$34:$K$37,0)) | AD46: =INDEX(CALC!$F$34:$F$37,MATCH(LARGE(CALC!$K$34:$K$37,1),CALC!$K$34:$K$37,0)) | AE46: =INDEX(CALC!$G$34:$G$37,MATCH(LARGE(CALC!$K$34:$K$37,1),CALC!$K$34:$K$37,0)) | AF46: =INDEX(CALC!$H$34:$H$37,MATCH(LARGE(CALC!$K$34:$K$37,1),CALC!$K$34:$K$37,0)) | AG46: =INDEX(CALC!$J$34:$J$37,MATCH(LARGE(CALC!$K$34:$K$37,1),CALC!$K$34:$K$37,0))
B47: 2 | C47: =INDEX(CALC!$B$26:$B$29,MATCH(LARGE(CALC!$K$26:$K$29,2),CALC!$K$26:$K$29,0)) | E47: =INDEX(CALC!$C$26:$C$29,MATCH(LARGE(CALC!$K$26:$K$29,2),CALC!$K$26:$K$29,0)) | F47: =INDEX(CALC!$D$26:$D$29,MATCH(LARGE(CALC!$K$26:$K$29,2),CALC!$K$26:$K$29,0)) | G47: =INDEX(CALC!$E$26:$E$29,MATCH(LARGE(CALC!$K$26:$K$29,2),CALC!$K$26:$K$29,0)) | H47: =INDEX(CALC!$F$26:$F$29,MATCH(LARGE(CALC!$K$26:$K$29,2),CALC!$K$26:$K$29,0)) | I47: =INDEX(CALC!$G$26:$G$29,MATCH(LARGE(CALC!$K$26:$K$29,2),CALC!$K$26:$K$29,0)) | J47: =INDEX(CALC!$H$26:$H$29,MATCH(LARGE(CALC!$K$26:$K$29,2),CALC!$K$26:$K$29,0)) | K47: =INDEX(CALC!$J$26:$J$29,MATCH(LARGE(CALC!$K$26:$K$29,2),CALC!$K$26:$K$29,0)) | M47: 2 | N47: =INDEX(CALC!$B$30:$B$33,MATCH(LARGE(CALC!$K$30:$K$33,2),CALC!$K$30:$K$33,0)) | P47: =INDEX(CALC!$C$30:$C$33,MATCH(LARGE(CALC!$K$30:$K$33,2),CALC!$K$30:$K$33,0)) | Q47: =INDEX(CALC!$D$30:$D$33,MATCH(LARGE(CALC!$K$30:$K$33,2),CALC!$K$30:$K$33,0)) | R47: =INDEX(CALC!$E$30:$E$33,MATCH(LARGE(CALC!$K$30:$K$33,2),CALC!$K$30:$K$33,0)) | S47: =INDEX(CALC!$F$30:$F$33,MATCH(LARGE(CALC!$K$30:$K$33,2),CALC!$K$30:$K$33,0)) | T47: =INDEX(CALC!$G$30:$G$33,MATCH(LARGE(CALC!$K$30:$K$33,2),CALC!$K$30:$K$33,0)) | U47: =INDEX(CALC!$H$30:$H$33,MATCH(LARGE(CALC!$K$30:$K$33,2),CALC!$K$30:$K$33,0)) | V47: =INDEX(CALC!$J$30:$J$33,MATCH(LARGE(CALC!$K$30:$K$33,2),CALC!$K$30:$K$33,0)) | X47: 2 | Y47: =INDEX(CALC!$B$34:$B$37,MATCH(LARGE(CALC!$K$34:$K$37,2),CALC!$K$34:$K$37,0)) | AA47: =INDEX(CALC!$C$34:$C$37,MATCH(LARGE(CALC!$K$34:$K$37,2),CALC!$K$34:$K$37,0)) | AB47: =INDEX(CALC!$D$34:$D$37,MATCH(LARGE(CALC!$K$34:$K$37,2),CALC!$K$34:$K$37,0)) | AC47: =INDEX(CALC!$E$34:$E$37,MATCH(LARGE(CALC!$K$34:$K$37,2),CALC!$K$34:$K$37,0)) | AD47: =INDEX(CALC!$F$34:$F$37,MATCH(LARGE(CALC!$K$34:$K$37,2),CALC!$K$34:$K$37,0)) | AE47: =INDEX(CALC!$G$34:$G$37,MATCH(LARGE(CALC!$K$34:$K$37,2),CALC!$K$34:$K$37,0)) | AF47: =INDEX(CALC!$H$34:$H$37,MATCH(LARGE(CALC!$K$34:$K$37,2),CALC!$K$34:$K$37,0)) | AG47: =INDEX(CALC!$J$34:$J$37,MATCH(LARGE(CALC!$K$34:$K$37,2),CALC!$K$34:$K$37,0))
...

Sheet CALC
A1: A | B1: Equipo | C1: PJ | D1: G | E1: E | F1: P | G1: GF | H1: GC | I1: DG | J1: PTS | K1: KEY
B2: México | C2: =COUNT('Fase de Grupos'!G4,'Fase de Grupos'!G7,'Fase de Grupos'!I8) | D2: =IF(AND(ISNUMBER('Fase de Grupos'!G4),ISNUMBER('Fase de Grupos'!I4)),IF('Fase de Grupos'!G4>'Fase de Grupos'!I4,1,0),0)+IF(AND(ISNUMBER('Fase de Grupos'!G7),ISNUMBER('Fase de Grupos'!I7)),IF('Fase de Grupos'!G7>'Fase de Grupos'!I7,1,0),0)+IF(AND(ISNUMBER('Fase de Grupos'!G8),ISNUMBER('Fase de Grupos'!I8)),IF('Fase de Grupos'!I8>'Fase de Grupos'!G8,1,0),0) | E2: =IF(AND(ISNUMBER('Fase de Grupos'!G4),ISNUMBER('Fase de Grupos'!I4)),IF('Fase de Grupos'!G4='Fase de Grupos'!I4,1,0),0)+IF(AND(ISNUMBER('Fase de Grupos'!G7),ISNUMBER('Fase de Grupos'!I7)),IF('Fase de Grupos'!G7='Fase de Grupos'!I7,1,0),0)+IF(AND(ISNUMBER('Fase de Grupos'!G8),ISNUMBER('Fase de Grupos'!I8)),IF('Fase de Grupos'!I8='Fase de Grupos'!G8,1,0),0) | F2: =IF(AND(ISNUMBER('Fase de Grupos'!G4),ISNUMBER('Fase de Grupos'!I4)),IF('Fase de Grupos'!G4<'Fase de Grupos'!I4,1,0),0)+IF(AND(ISNUMBER('Fase de Grupos'!G7),ISNUMBER('Fase de Grupos'!I7)),IF('Fase de Grupos'!G7<'Fase de Grupos'!I7,1,0),0)+IF(AND(ISNUMBER('Fase de Grupos'!G8),ISNUMBER('Fase de Grupos'!I8)),IF('Fase de Grupos'!I8<'Fase de Grupos'!G8,1,0),0) | G2: =SUM('Fase de Grupos'!G4,'Fase de Grupos'!G7,'Fase de Grupos'!I8) | H2: =SUM('Fase de Grupos'!I4,'Fase de Grupos'!I7,'Fase de Grupos'!G8) | I2: =G2-H2 | J2: =D2*3+E2 | K2: =J2*100000+(I2+1000)*100+G2*10+3
B3: Sudáfrica | C3: =COUNT('Fase de Grupos'!G9,'Fase de Grupos'!I4,'Fase de Grupos'!I6) | D3: =IF(AND(ISNUMBER('Fase de Grupos'!G9),ISNUMBER('Fase de Grupos'!I9)),IF('Fase de Grupos'!G9>'Fase de Grupos'!I9,1,0),0)+IF(AND(ISNUMBER('Fase de Grupos'!G4),ISNUMBER('Fase de Grupos'!I4)),IF('Fase de Grupos'!I4>'Fase de Grupos'!G4,1,0),0)+IF(AND(ISNUMBER('Fase de Grupos'!G6),ISNUMBER('Fase de Grupos'!I6)),IF('Fase de Grupos'!I6>'Fase de Grupos'!G6,1,0),0) | E3: =IF(AND(ISNUMBER('Fase de Grupos'!G9),ISNUMBER('Fase de Grupos'!I9)),IF('Fase de Grupos'!G9='Fase de Grupos'!I9,1,0),0)+IF(AND(ISNUMBER('Fase de Grupos'!G4),ISNUMBER('Fase de Grupos'!I4)),IF('Fase de Grupos'!I4='Fase de Grupos'!G4,1,0),0)+IF(AND(ISNUMBER('Fase de Grupos'!G6),ISNUMBER('Fase de Grupos'!I6)),IF('Fase de Grupos'!I6='Fase de Grupos'!G6,1,0),0) | F3: =IF(AND(ISNUMBER('Fase de Grupos'!G9),ISNUMBER('Fase de Grupos'!I9)),IF('Fase de Grupos'!G9<'Fase de Grupos'!I9,1,0),0)+IF(AND(ISNUMBER('Fase de Grupos'!G4),ISNUMBER('Fase de Grupos'!I4)),IF('Fase de Grupos'!I4<'Fase de Grupos'!G4,1,0),0)+IF(AND(ISNUMBER('Fase de Grupos'!G6),ISNUMBER('Fase de Grupos'!I6)),IF('Fase de Grupos'!I6<'Fase de Grupos'!G6,1,0),0) | G3: =SUM('Fase de Grupos'!G9,'Fase de Grupos'!I4,'Fase de Grupos'!I6) | H3: =SUM('Fase de Grupos'!I9,'Fase de Grupos'!G4,'Fase de Grupos'!G6) | I3: =G3-H3 | J3: =D3*3+E3 | K3: =J3*100000+(I3+1000)*100+G3*10+2
B4: Corea del Sur | C4: =COUNT('Fase de Grupos'!G5,'Fase de Grupos'!I7,'Fase de Grupos'!I9) | D4: =IF(AND(ISNUMBER('Fase de Grupos'!G5),ISNUMBER('Fase de Grupos'!I5)),IF('Fase de Grupos'!G5>'Fase de Grupos'!I5,1,0),0)+IF(AND(ISNUMBER('Fase de Grupos'!G7),ISNUMBER('Fase de Grupos'!I7)),IF('Fase de Grupos'!I7>'Fase de Grupos'!G7,1,0),0)+IF(AND(ISNUMBER('Fase de Grupos'!G9),ISNUMBER('Fase de Grupos'!I9)),IF('Fase de Grupos'!I9>'Fase de Grupos'!G9,1,0),0) | E4: =IF(AND(ISNUMBER('Fase de Grupos'!G5),ISNUMBER('Fase de Grupos'!I5)),IF('Fase de Grupos'!G5='Fase de Grupos'!I5,1,0),0)+IF(AND(ISNUMBER('Fase de Grupos'!G7),ISNUMBER('Fase de Grupos'!I7)),IF('Fase de Grupos'!I7='Fase de Grupos'!G7,1,0),0)+IF(AND(ISNUMBER('Fase de Grupos'!G9),ISNUMBER('Fase de Grupos'!I9)),IF('Fase de Grupos'!I9='Fase de Grupos'!G9,1,0),0) | F4: =IF(AND(ISNUMBER('Fase de Grupos'!G5),ISNUMBER('Fase de Grupos'!I5)),IF('Fase de Grupos'!G5<'Fase de Grupos'!I5,1,0),0)+IF(AND(ISNUMBER('Fase de Grupos'!G7),ISNUMBER('Fase de Grupos'!I7)),IF('Fase de Grupos'!I7<'Fase de Grupos'!G7,1,0),0)+IF(AND(ISNUMBER('Fase de Grupos'!G9),ISNUMBER('Fase de Grupos'!I9)),IF('Fase de Grupos'!I9<'Fase de Grupos'!G9,1,0),0) | G4: =SUM('Fase de Grupos'!G5,'Fase de Grupos'!I7,'Fase de Grupos'!I9) | H4: =SUM('Fase de Grupos'!I5,'Fase de Grupos'!G7,'Fase de Grupos'!G9) | I4: =G4-H4 | J4: =D4*3+E4 | K4: =J4*100000+(I4+1000)*100+G4*10+1
A5: B | B5: República Checa | C5: =COUNT('Fase de Grupos'!G6,'Fase de Grupos'!G8,'Fase de Grupos'!I5) | D5: =IF(AND(ISNUMBER('Fase de Grupos'!G6),ISNUMBER('Fase de Grupos'!I6)),IF('Fase de Grupos'!G6>'Fase de Grupos'!I6,1,0),0)+IF(AND(ISNUMBER('Fase de Grupos'!G8),ISNUMBER('Fase de Grupos'!I8)),IF('Fase de Grupos'!G8>'Fase de Grupos'!I8,1,0),0)+IF(AND(ISNUMBER('Fase de Grupos'!G5),ISNUMBER('Fase de Grupos'!I5)),IF('Fase de Grupos'!I5>'Fase de Grupos'!G5,1,0),0) | E5: =IF(AND(ISNUMBER('Fase de Grupos'!G6),ISNUMBER('Fase de Grupos'!I6)),IF('Fase de Grupos'!G6='Fase de Grupos'!I6,1,0),0)+IF(AND(ISNUMBER('Fase de Grupos'!G8),ISNUMBER('Fase de Grupos'!I8)),IF('Fase de Grupos'!G8='Fase de Grupos'!I8,1,0),0)+IF(AND(ISNUMBER('Fase de Grupos'!G5),ISNUMBER('Fase de Grupos'!I5)),IF('Fase de Grupos'!I5='Fase de Grupos'!G5,1,0),0) | F5: =IF(AND(ISNUMBER('Fase de Grupos'!G6),ISNUMBER('Fase de Grupos'!I6)),IF('Fase de Grupos'!G6<'Fase de Grupos'!I6,1,0),0)+IF(AND(ISNUMBER('Fase de Grupos'!G8),ISNUMBER('Fase de Grupos'!I8)),IF('Fase de Grupos'!G8<'Fase de Grupos'!I8,1,0),0)+IF(AND(ISNUMBER('Fase de Grupos'!G5),ISNUMBER('Fase de Grupos'!I5)),IF('Fase de Grupos'!I5<'Fase de Grupos'!G5,1,0),0) | G5: =SUM('Fase de Grupos'!G6,'Fase de Grupos'!G8,'Fase de Grupos'!I5) | H5: =SUM('Fase de Grupos'!I6,'Fase de Grupos'!I8,'Fase de Grupos'!G5) | I5: =G5-H5 | J5: =D5*3+E5 | K5: =J5*100000+(I5+1000)*100+G5*10+0
B6: Canadá | C6: =COUNT('Fase de Grupos'!R4,'Fase de Grupos'!R7,'Fase de Grupos'!T8) | D6: =IF(AND(ISNUMBER('Fase de Grupos'!R4),ISNUMBER('Fase de Grupos'!T4)),IF('Fase de Grupos'!R4>'Fase de Grupos'!T4,1,0),0)+IF(AND(ISNUMBER('Fase de Grupos'!R7),ISNUMBER('Fase de Grupos'!T7)),IF('Fase de Grupos'!R7>'Fase de Grupos'!T7,1,0),0)+IF(AND(ISNUMBER('Fase de Grupos'!R8),ISNUMBER('Fase de Grupos'!T8)),IF('Fase de Grupos'!T8>'Fase de Grupos'!R8,1,0),0) | E6: =IF(AND(ISNUMBER('Fase de Grupos'!R4),ISNUMBER('Fase de Grupos'!T4)),IF('Fase de Grupos'!R4='Fase de Grupos'!T4,1,0),0)+IF(AND(ISNUMBER('Fase de Grupos'!R7),ISNUMBER('Fase de Grupos'!T7)),IF('Fase de Grupos'!R7='Fase de Grupos'!T7,1,0),0)+IF(AND(ISNUMBER('Fase de Grupos'!R8),ISNUMBER('Fase de Grupos'!T8)),IF('Fase de Grupos'!T8='Fase de Grupos'!R8,1,0),0) | F6: =IF(AND(ISNUMBER('Fase de Grupos'!R4),ISNUMBER('Fase de Grupos'!T4)),IF('Fase de Grupos'!R4<'Fase de Grupos'!T4,1,0),0)+IF(AND(ISNUMBER('Fase de Grupos'!R7),ISNUMBER('Fase de Grupos'!T7)),IF('Fase de Grupos'!R7<'Fase de Grupos'!T7,1,0),0)+IF(AND(ISNUMBER('Fase de Grupos'!R8),ISNUMBER('Fase de Grupos'!T8)),IF('Fase de Grupos'!T8<'Fase de Grupos'!R8,1,0),0) | G6: =SUM('Fase de Grupos'!R4,'Fase de Grupos'!R7,'Fase de Grupos'!T8) | H6: =SUM('Fase de Grupos'!T4,'Fase de Grupos'!T7,'Fase de Grupos'!R8) | I6: =G6-H6 | J6: =D6*3+E6 | K6: =J6*100000+(I6+1000)*100+G6*10+3
B7: Suiza | C7: =COUNT('Fase de Grupos'!R6,'Fase de Grupos'!R8,'Fase de Grupos'!T5) | D7: =IF(AND(ISNUMBER('Fase de Grupos'!R6),ISNUMBER('Fase de Grupos'!T6)),IF('Fase de Grupos'!R6>'Fase de Grupos'!T6,1,0),0)+IF(AND(ISNUMBER('Fase de Grupos'!R8),ISNUMBER('Fase de Grupos'!T8)),IF('Fase de Grupos'!R8>'Fase de Grupos'!T8,1,0),0)+IF(AND(ISNUMBER('Fase de Grupos'!R5),ISNUMBER('Fase de Grupos'!T5)),IF('Fase de Grupos'!T5>'Fase de Grupos'!R5,1,0),0) | E7: =IF(AND(ISNUMBER('Fase de Grupos'!R6),ISNUMBER('Fase de Grupos'!T6)),IF('Fase de Grupos'!R6='Fase de Grupos'!T6,1,0),0)+IF(AND(ISNUMBER('Fase de Grupos'!R8),ISNUMBER('Fase de Grupos'!T8)),IF('Fase de Grupos'!R8='Fase de Grupos'!T8,1,0),0)+IF(AND(ISNUMBER('Fase de Grupos'!R5),ISNUMBER('Fase de Grupos'!T5)),IF('Fase de Grupos'!T5='Fase de Grupos'!R5,1,0),0) | F7: =IF(AND(ISNUMBER('Fase de Grupos'!R6),ISNUMBER('Fase de Grupos'!T6)),IF('Fase de Grupos'!R6<'Fase de Grupos'!T6,1,0),0)+IF(AND(ISNUMBER('Fase de Grupos'!R8),ISNUMBER('Fase de Grupos'!T8)),IF('Fase de Grupos'!R8<'Fase de Grupos'!T8,1,0),0)+IF(AND(ISNUMBER('Fase de Grupos'!R5),ISNUMBER('Fase de Grupos'!T5)),IF('Fase de Grupos'!T5<'Fase de Grupos'!R5,1,0),0) | G7: =SUM('Fase de Grupos'!R6,'Fase de Grupos'!R8,'Fase de Grupos'!T5) | H7: =SUM('Fase de Grupos'!T6,'Fase de Grupos'!T8,'Fase de Grupos'!R5) | I7: =G7-H7 | J7: =D7*3+E7 | K7: =J7*100000+(I7+1000)*100+G7*10+2
B8: Catar | C8: =COUNT('Fase de Grupos'!R5,'Fase de Grupos'!T7,'Fase de Grupos'!T9) | D8: =IF(AND(ISNUMBER('Fase de Grupos'!R5),ISNUMBER('Fase de Grupos'!T5)),IF('Fase de Grupos'!R5>'Fase de Grupos'!T5,1,0),0)+IF(AND(ISNUMBER('Fase de Grupos'!R7),ISNUMBER('Fase de Grupos'!T7)),IF('Fase de Grupos'!T7>'Fase de Grupos'!R7,1,0),0)+IF(AND(ISNUMBER('Fase de Grupos'!R9),ISNUMBER('Fase de Grupos'!T9)),IF('Fase de Grupos'!T9>'Fase de Grupos'!R9,1,0),0) | E8: =IF(AND(ISNUMBER('Fase de Grupos'!R5),ISNUMBER('Fase de Grupos'!T5)),IF('Fase de Grupos'!R5='Fase de Grupos'!T5,1,0),0)+IF(AND(ISNUMBER('Fase de Grupos'!R7),ISNUMBER('Fase de Grupos'!T7)),IF('Fase de Grupos'!T7='Fase de Grupos'!R7,1,0),0)+IF(AND(ISNUMBER('Fase de Grupos'!R9),ISNUMBER('Fase de Grupos'!T9)),IF('Fase de Grupos'!T9='Fase de Grupos'!R9,1,0),0) | F8: =IF(AND(ISNUMBER('Fase de Grupos'!R5),ISNUMBER('Fase de Grupos'!T5)),IF('Fase de Grupos'!R5<'Fase de Grupos'!T5,1,0),0)+IF(AND(ISNUMBER('Fase de Grupos'!R7),ISNUMBER('Fase de Grupos'!T7)),IF('Fase de Grupos'!T7<'Fase de Grupos'!R7,1,0),0)+IF(AND(ISNUMBER('Fase de Grupos'!R9),ISNUMBER('Fase de Grupos'!T9)),IF('Fase de Grupos'!T9<'Fase de Grupos'!R9,1,0),0) | G8: =SUM('Fase de Grupos'!R5,'Fase de Grupos'!T7,'Fase de Grupos'!T9) | H8: =SUM('Fase de Grupos'!T5,'Fase de Grupos'!R7,'Fase de Grupos'!R9) | I8: =G8-H8 | J8: =D8*3+E8 | K8: =J8*100000+(I8+1000)*100+G8*10+1
A9: C | B9: Bosnia y Herz. | C9: =COUNT('Fase de Grupos'!R9,'Fase de Grupos'!T4,'Fase de Grupos'!T6) | D9: =IF(AND(ISNUMBER('Fase de Grupos'!R9),ISNUMBER('Fase de Grupos'!T9)),IF('Fase de Grupos'!R9>'Fase de Grupos'!T9,1,0),0)+IF(AND(ISNUMBER('Fase de Grupos'!R4),ISNUMBER('Fase de Grupos'!T4)),IF('Fase de Grupos'!T4>'Fase de Grupos'!R4,1,0),0)+IF(AND(ISNUMBER('Fase de Grupos'!R6),ISNUMBER('Fase de Grupos'!T6)),IF('Fase de Grupos'!T6>'Fase de Grupos'!R6,1,0),0) | E9: =IF(AND(ISNUMBER('Fase de Grupos'!R9),ISNUMBER('Fase de Grupos'!T9)),IF('Fase de Grupos'!R9='Fase de Grupos'!T9,1,0),0)+IF(AND(ISNUMBER('Fase de Grupos'!R4),ISNUMBER('Fase de Grupos'!T4)),IF('Fase de Grupos'!T4='Fase de Grupos'!R4,1,0),0)+IF(AND(ISNUMBER('Fase de Grupos'!R6),ISNUMBER('Fase de Grupos'!T6)),IF('Fase de Grupos'!T6='Fase de Grupos'!R6,1,0),0) | F9: =IF(AND(ISNUMBER('Fase de Grupos'!R9),ISNUMBER('Fase de Grupos'!T9)),IF('Fase de Grupos'!R9<'Fase de Grupos'!T9,1,0),0)+IF(AND(ISNUMBER('Fase de Grupos'!R4),ISNUMBER('Fase de Grupos'!T4)),IF('Fase de Grupos'!T4<'Fase de Grupos'!R4,1,0),0)+IF(AND(ISNUMBER('Fase de Grupos'!R6),ISNUMBER('Fase de Grupos'!T6)),IF('Fase de Grupos'!T6<'Fase de Grupos'!R6,1,0),0) | G9: =SUM('Fase de Grupos'!R9,'Fase de Grupos'!T4,'Fase de Grupos'!T6) | H9: =SUM('Fase de Grupos'!T9,'Fase de Grupos'!R4,'Fase de Grupos'!R6) | I9: =G9-H9 | J9: =D9*3+E9 | K9: =J9*100000+(I9+1000)*100+G9*10+0
B10: Brasil | C10: =COUNT('Fase de Grupos'!AC5,'Fase de Grupos'!AC6,'Fase de Grupos'!AE8) | D10: =IF(AND(ISNUMBER('Fase de Grupos'!AC5),ISNUMBER('Fase de Grupos'!AE5)),IF('Fase de Grupos'!AC5>'Fase de Grupos'!AE5,1,0),0)+IF(AND(ISNUMBER('Fase de Grupos'!AC6),ISNUMBER('Fase de Grupos'!AE6)),IF('Fase de Grupos'!AC6>'Fase de Grupos'!AE6,1,0),0)+IF(AND(ISNUMBER('Fase de Grupos'!AC8),ISNUMBER('Fase de Grupos'!AE8)),IF('Fase de Grupos'!AE8>'Fase de Grupos'!AC8,1,0),0) | E10: =IF(AND(ISNUMBER('Fase de Grupos'!AC5),ISNUMBER('Fase de Grupos'!AE5)),IF('Fase de Grupos'!AC5='Fase de Grupos'!AE5,1,0),0)+IF(AND(ISNUMBER('Fase de Grupos'!AC6),ISNUMBER('Fase de Grupos'!AE6)),IF('Fase de Grupos'!AC6='Fase de Grupos'!AE6,1,0),0)+IF(AND(ISNUMBER('Fase de Grupos'!AC8),ISNUMBER('Fase de Grupos'!AE8)),IF('Fase de Grupos'!AE8='Fase de Grupos'!AC8,1,0),0) | F10: =IF(AND(ISNUMBER('Fase de Grupos'!AC5),ISNUMBER('Fase de Grupos'!AE5)),IF('Fase de Grupos'!AC5<'Fase de Grupos'!AE5,1,0),0)+IF(AND(ISNUMBER('Fase de Grupos'!AC6),ISNUMBER('Fase de Grupos'!AE6)),IF('Fase de Grupos'!AC6<'Fase de Grupos'!AE6,1,0),0)+IF(AND(ISNUMBER('Fase de Grupos'!AC8),ISNUMBER('Fase de Grupos'!AE8)),IF('Fase de Grupos'!AE8<'Fase de Grupos'!AC8,1,0),0) | G10: =SUM('Fase de Grupos'!AC5,'Fase de Grupos'!AC6,'Fase de Grupos'!AE8) | H10: =SUM('Fase de Grupos'!AE5,'Fase de Grupos'!AE6,'Fase de Grupos'!AC8) | I10: =G10-H10 | J10: =D10*3+E10 | K10: =J10*100000+(I10+1000)*100+G10*10+3
B11: Marruecos | C11: =COUNT('Fase de Grupos'!AC9,'Fase de Grupos'!AE5,'Fase de Grupos'!AE7) | D11: =IF(AND(ISNUMBER('Fase de Grupos'!AC9),ISNUMBER('Fase de Grupos'!AE9)),IF('Fase de Grupos'!AC9>'Fase de Grupos'!AE9,1,0),0)+IF(AND(ISNUMBER('Fase de Grupos'!AC5),ISNUMBER('Fase de Grupos'!AE5)),IF('Fase de Grupos'!AE5>'Fase de Grupos'!AC5,1,0),0)+IF(AND(ISNUMBER('Fase de Grupos'!AC7),ISNUMBER('Fase de Grupos'!AE7)),IF('Fase de Grupos'!AE7>'Fase de Grupos'!AC7,1,0),0) | E11: =IF(AND(ISNUMBER('Fase de Grupos'!AC9),ISNUMBER('Fase de Grupos'!AE9)),IF('Fase de Grupos'!AC9='Fase de Grupos'!AE9,1,0),0)+IF(AND(ISNUMBER('Fase de Grupos'!AC5),ISNUMBER('Fase de Grupos'!AE5)),IF('Fase de Grupos'!AE5='Fase de Grupos'!AC5,1,0),0)+IF(AND(ISNUMBER('Fase de Grupos'!AC7),ISNUMBER('Fase de Grupos'!AE7)),IF('Fase de Grupos'!AE7='Fase de Grupos'!AC7,1,0),0) | F11: =IF(AND(ISNUMBER('Fase de Grupos'!AC9),ISNUMBER('Fase de Grupos'!AE9)),IF('Fase de Grupos'!AC9<'Fase de Grupos'!AE9,1,0),0)+IF(AND(ISNUMBER('Fase de Grupos'!AC5),ISNUMBER('Fase de Grupos'!AE5)),IF('Fase de Grupos'!AE5<'Fase de Grupos'!AC5,1,0),0)+IF(AND(ISNUMBER('Fase de Grupos'!AC7),ISNUMBER('Fase de Grupos'!AE7)),IF('Fase de Grupos'!AE7<'Fase de Grupos'!AC7,1,0),0) | G11: =SUM('Fase de Grupos'!AC9,'Fase de Grupos'!AE5,'Fase de Grupos'!AE7) | H11: =SUM('Fase de Grupos'!AE9,'Fase de Grupos'!AC5,'Fase de Grupos'!AC7) | I11: =G11-H11 | J11: =D11*3+E11 | K11: =J11*100000+(I11+1000)*100+G11*10+2
B12: Escocia | C12: =COUNT('Fase de Grupos'!AC7,'Fase de Grupos'!AC8,'Fase de Grupos'!AE4) | D12: =IF(AND(ISNUMBER('Fase de Grupos'!AC7),ISNUMBER('Fase de Grupos'!AE7)),IF('Fase de Grupos'!AC7>'Fase de Grupos'!AE7,1,0),0)+IF(AND(ISNUMBER('Fase de Grupos'!AC8),ISNUMBER('Fase de Grupos'!AE8)),IF('Fase de Grupos'!AC8>'Fase de Grupos'!AE8,1,0),0)+IF(AND(ISNUMBER('Fase de Grupos'!AC4),ISNUMBER('Fase de Grupos'!AE4)),IF('Fase de Grupos'!AE4>'Fase de Grupos'!AC4,1,0),0) | E12: =IF(AND(ISNUMBER('Fase de Grupos'!AC7),ISNUMBER('Fase de Grupos'!AE7)),IF('Fase de Grupos'!AC7='Fase de Grupos'!AE7,1,0),0)+IF(AND(ISNUMBER('Fase de Grupos'!AC8),ISNUMBER('Fase de Grupos'!AE8)),IF('Fase de Grupos'!AC8='Fase de Grupos'!AE8,1,0),0)+IF(AND(ISNUMBER('Fase de Grupos'!AC4),ISNUMBER('Fase de Grupos'!AE4)),IF('Fase de Grupos'!AE4='Fase de Grupos'!AC4,1,0),0) | F12: =IF(AND(ISNUMBER('Fase de Grupos'!AC7),ISNUMBER('Fase de Grupos'!AE7)),IF('Fase de Grupos'!AC7<'Fase de Grupos'!AE7,1,0),0)+IF(AND(ISNUMBER('Fase de Grupos'!AC8),ISNUMBER('Fase de Grupos'!AE8)),IF('Fase de Grupos'!AC8<'Fase de Grupos'!AE8,1,0),0)+IF(AND(ISNUMBER('Fase de Grupos'!AC4),ISNUMBER('Fase de Grupos'!AE4)),IF('Fase de Grupos'!AE4<'Fase de Grupos'!AC4,1,0),0) | G12: =SUM('Fase de Grupos'!AC7,'Fase de Grupos'!AC8,'Fase de Grupos'!AE4) | H12: =SUM('Fase de Grupos'!AE7,'Fase de Grupos'!AE8,'Fase de Grupos'!AC4) | I12: =G12-H12 | J12: =D12*3+E12 | K12: =J12*100000+(I12+1000)*100+G12*10+1
A13: D | B13: Haití | C13: =COUNT('Fase de Grupos'!AC4,'Fase de Grupos'!AE6,'Fase de Grupos'!AE9) | D13: =IF(AND(ISNUMBER('Fase de Grupos'!AC4),ISNUMBER('Fase de Grupos'!AE4)),IF('Fase de Grupos'!AC4>'Fase de Grupos'!AE4,1,0),0)+IF(AND(ISNUMBER('Fase de Grupos'!AC6),ISNUMBER('Fase de Grupos'!AE6)),IF('Fase de Grupos'!AE6>'Fase de Grupos'!AC6,1,0),0)+IF(AND(ISNUMBER('Fase de Grupos'!AC9),ISNUMBER('Fase de Grupos'!AE9)),IF('Fase de Grupos'!AE9>'Fase de Grupos'!AC9,1,0),0) | E13: =IF(AND(ISNUMBER('Fase de Grupos'!AC4),ISNUMBER('Fase de Grupos'!AE4)),IF('Fase de Grupos'!AC4='Fase de Grupos'!AE4,1,0),0)+IF(AND(ISNUMBER('Fase de Grupos'!AC6),ISNUMBER('Fase de Grupos'!AE6)),IF('Fase de Grupos'!AE6='Fase de Grupos'!AC6,1,0),0)+IF(AND(ISNUMBER('Fase de Grupos'!AC9),ISNUMBER('Fase de Grupos'!AE9)),IF('Fase de Grupos'!AE9='Fase de Grupos'!AC9,1,0),0) | F13: =IF(AND(ISNUMBER('Fase de Grupos'!AC4),ISNUMBER('Fase de Grupos'!AE4)),IF('Fase de Grupos'!AC4<'Fase de Grupos'!AE4,1,0),0)+IF(AND(ISNUMBER('Fase de Grupos'!AC6),ISNUMBER('Fase de Grupos'!AE6)),IF('Fase de Grupos'!AE6<'Fase de Grupos'!AC6,1,0),0)+IF(AND(ISNUMBER('Fase de Grupos'!AC9),ISNUMBER('Fase de Grupos'!AE9)),IF('Fase de Grupos'!AE9<'Fase de Grupos'!AC9,1,0),0) | G13: =SUM('Fase de Grupos'!AC4,'Fase de Grupos'!AE6,'Fase de Grupos'!AE9) | H13: =SUM('Fase de Grupos'!AE4,'Fase de Grupos'!AC6,'Fase de Grupos'!AC9) | I13: =G13-H13 | J13: =D13*3+E13 | K13: =J13*100000+(I13+1000)*100+G13*10+0
B14: Estados Unidos | C14: =COUNT('Fase de Grupos'!G21,'Fase de Grupos'!G24,'Fase de Grupos'!I25) | D14: =IF(AND(ISNUMBER('Fase de Grupos'!G21),ISNUMBER('Fase de Grupos'!I21)),IF('Fase de Grupos'!G21>'Fase de Grupos'!I21,1,0),0)+IF(AND(ISNUMBER('Fase de Grupos'!G24),ISNUMBER('Fase de Grupos'!I24)),IF('Fase de Grupos'!G24>'Fase de Grupos'!I24,1,0),0)+IF(AND(ISNUMBER('Fase de Grupos'!G25),ISNUMBER('Fase de Grupos'!I25)),IF('Fase de Grupos'!I25>'Fase de Grupos'!G25,1,0),0) | E14: =IF(AND(ISNUMBER('Fase de Grupos'!G21),ISNUMBER('Fase de Grupos'!I21)),IF('Fase de Grupos'!G21='Fase de Grupos'!I21,1,0),0)+IF(AND(ISNUMBER('Fase de Grupos'!G24),ISNUMBER('Fase de Grupos'!I24)),IF('Fase de Grupos'!G24='Fase de Grupos'!I24,1,0),0)+IF(AND(ISNUMBER('Fase de Grupos'!G25),ISNUMBER('Fase de Grupos'!I25)),IF('Fase de Grupos'!I25='Fase de Grupos'!G25,1,0),0) | F14: =IF(AND(ISNUMBER('Fase de Grupos'!G21),ISNUMBER('Fase de Grupos'!I21)),IF('Fase de Grupos'!G21<'Fase de Grupos'!I21,1,0),0)+IF(AND(ISNUMBER('Fase de Grupos'!G24),ISNUMBER('Fase de Grupos'!I24)),IF('Fase de Grupos'!G24<'Fase de Grupos'!I24,1,0),0)+IF(AND(ISNUMBER('Fase de Grupos'!G25),ISNUMBER('Fase de Grupos'!I25)),IF('Fase de Grupos'!I25<'Fase de Grupos'!G25,1,0),0) | G14: =SUM('Fase de Grupos'!G21,'Fase de Grupos'!G24,'Fase de Grupos'!I25) | H14: =SUM('Fase de Grupos'!I21,'Fase de Grupos'!I24,'Fase de Grupos'!G25) | I14: =G14-H14 | J14: =D14*3+E14 | K14: =J14*100000+(I14+1000)*100+G14*10+3
B15: Paraguay | C15: =COUNT('Fase de Grupos'!G26,'Fase de Grupos'!I21,'Fase de Grupos'!I23) | D15: =IF(AND(ISNUMBER('Fase de Grupos'!G26),ISNUMBER('Fase de Grupos'!I26)),IF('Fase de Grupos'!G26>'Fase de Grupos'!I26,1,0),0)+IF(AND(ISNUMBER('Fase de Grupos'!G21),ISNUMBER('Fase de Grupos'!I21)),IF('Fase de Grupos'!I21>'Fase de Grupos'!G21,1,0),0)+IF(AND(ISNUMBER('Fase de Grupos'!G23),ISNUMBER('Fase de Grupos'!I23)),IF('Fase de Grupos'!I23>'Fase de Grupos'!G23,1,0),0) | E15: =IF(AND(ISNUMBER('Fase de Grupos'!G26),ISNUMBER('Fase de Grupos'!I26)),IF('Fase de Grupos'!G26='Fase de Grupos'!I26,1,0),0)+IF(AND(ISNUMBER('Fase de Grupos'!G21),ISNUMBER('Fase de Grupos'!I21)),IF('Fase de Grupos'!I21='Fase de Grupos'!G21,1,0),0)+IF(AND(ISNUMBER('Fase de Grupos'!G23),ISNUMBER('Fase de Grupos'!I23)),IF('Fase de Grupos'!I23='Fase de Grupos'!G23,1,0),0) | F15: =IF(AND(ISNUMBER('Fase de Grupos'!G26),ISNUMBER('Fase de Grupos'!I26)),IF('Fase de Grupos'!G26<'Fase de Grupos'!I26,1,0),0)+IF(AND(ISNUMBER('Fase de Grupos'!G21),ISNUMBER('Fase de Grupos'!I21)),IF('Fase de Grupos'!I21<'Fase de Grupos'!G21,1,0),0)+IF(AND(ISNUMBER('Fase de Grupos'!G23),ISNUMBER('Fase de Grupos'!I23)),IF('Fase de Grupos'!I23<'Fase de Grupos'!G23,1,0),0) | G15: =SUM('Fase de Grupos'!G26,'Fase de Grupos'!I21,'Fase de Grupos'!I23) | H15: =SUM('Fase de Grupos'!I26,'Fase de Grupos'!G21,'Fase de Grupos'!G23) | I15: =G15-H15 | J15: =D15*3+E15 | K15: =J15*100000+(I15+1000)*100+G15*10+2
B16: Australia | C16: =COUNT('Fase de Grupos'!G22,'Fase de Grupos'!I24,'Fase de Grupos'!I26) | D16: =IF(AND(ISNUMBER('Fase de Grupos'!G22),ISNUMBER('Fase de Grupos'!I22)),IF('Fase de Grupos'!G22>'Fase de Grupos'!I22,1,0),0)+IF(AND(ISNUMBER('Fase de Grupos'!G24),ISNUMBER('Fase de Grupos'!I24)),IF('Fase de Grupos'!I24>'Fase de Grupos'!G24,1,0),0)+IF(AND(ISNUMBER('Fase de Grupos'!G26),ISNUMBER('Fase de Grupos'!I26)),IF('Fase de Grupos'!I26>'Fase de Grupos'!G26,1,0),0) | E16: =IF(AND(ISNUMBER('Fase de Grupos'!G22),ISNUMBER('Fase de Grupos'!I22)),IF('Fase de Grupos'!G22='Fase de Grupos'!I22,1,0),0)+IF(AND(ISNUMBER('Fase de Grupos'!G24),ISNUMBER('Fase de Grupos'!I24)),IF('Fase de Grupos'!I24='Fase de Grupos'!G24,1,0),0)+IF(AND(ISNUMBER('Fase de Grupos'!G26),ISNUMBER('Fase de Grupos'!I26)),IF('Fase de Grupos'!I26='Fase de Grupos'!G26,1,0),0) | F16: =IF(AND(ISNUMBER('Fase de Grupos'!G22),ISNUMBER('Fase de Grupos'!I22)),IF('Fase de Grupos'!G22<'Fase de Grupos'!I22,1,0),0)+IF(AND(ISNUMBER('Fase de Grupos'!G24),ISNUMBER('Fase de Grupos'!I24)),IF('Fase de Grupos'!I24<'Fase de Grupos'!G24,1,0),0)+IF(AND(ISNUMBER('Fase de Grupos'!G26),ISNUMBER('Fase de Grupos'!I26)),IF('Fase de Grupos'!I26<'Fase de Grupos'!G26,1,0),0) | G16: =SUM('Fase de Grupos'!G22,'Fase de Grupos'!I24,'Fase de Grupos'!I26) | H16: =SUM('Fase de Grupos'!I22,'Fase de Grupos'!G24,'Fase de Grupos'!G26) | I16: =G16-H16 | J16: =D16*3+E16 | K16: =J16*100000+(I16+1000)*100+G16*10+1
A17: E | B17: Turquía | C17: =COUNT('Fase de Grupos'!G23,'Fase de Grupos'!G25,'Fase de Grupos'!I22) | D17: =IF(AND(ISNUMBER('Fase de Grupos'!G23),ISNUMBER('Fase de Grupos'!I23)),IF('Fase de Grupos'!G23>'Fase de Grupos'!I23,1,0),0)+IF(AND(ISNUMBER('Fase de Grupos'!G25),ISNUMBER('Fase de Grupos'!I25)),IF('Fase de Grupos'!G25>'Fase de Grupos'!I25,1,0),0)+IF(AND(ISNUMBER('Fase de Grupos'!G22),ISNUMBER('Fase de Grupos'!I22)),IF('Fase de Grupos'!I22>'Fase de Grupos'!G22,1,0),0) | E17: =IF(AND(ISNUMBER('Fase de Grupos'!G23),ISNUMBER('Fase de Grupos'!I23)),IF('Fase de Grupos'!G23='Fase de Grupos'!I23,1,0),0)+IF(AND(ISNUMBER('Fase de Grupos'!G25),ISNUMBER('Fase de Grupos'!I25)),IF('Fase de Grupos'!G25='Fase de Grupos'!I25,1,0),0)+IF(AND(ISNUMBER('Fase de Grupos'!G22),ISNUMBER('Fase de Grupos'!I22)),IF('Fase de Grupos'!I22='Fase de Grupos'!G22,1,0),0) | F17: =IF(AND(ISNUMBER('Fase de Grupos'!G23),ISNUMBER('Fase de Grupos'!I23)),IF('Fase de Grupos'!G23<'Fase de Grupos'!I23,1,0),0)+IF(AND(ISNUMBER('Fase de Grupos'!G25),ISNUMBER('Fase de Grupos'!I25)),IF('Fase de Grupos'!G25<'Fase de Grupos'!I25,1,0),0)+IF(AND(ISNUMBER('Fase de Grupos'!G22),ISNUMBER('Fase de Grupos'!I22)),IF('Fase de Grupos'!I22<'Fase de Grupos'!G22,1,0),0) | G17: =SUM('Fase de Grupos'!G23,'Fase de Grupos'!G25,'Fase de Grupos'!I22) | H17: =SUM('Fase de Grupos'!I23,'Fase de Grupos'!I25,'Fase de Grupos'!G22) | I17: =G17-H17 | J17: =D17*3+E17 | K17: =J17*100000+(I17+1000)*100+G17*10+0
B18: Alemania | C18: =COUNT('Fase de Grupos'!R22,'Fase de Grupos'!R23,'Fase de Grupos'!T26) | D18: =IF(AND(ISNUMBER('Fase de Grupos'!R22),ISNUMBER('Fase de Grupos'!T22)),IF('Fase de Grupos'!R22>'Fase de Grupos'!T22,1,0),0)+IF(AND(ISNUMBER('Fase de Grupos'!R23),ISNUMBER('Fase de Grupos'!T23)),IF('Fase de Grupos'!R23>'Fase de Grupos'!T23,1,0),0)+IF(AND(ISNUMBER('Fase de Grupos'!R26),ISNUMBER('Fase de Grupos'!T26)),IF('Fase de Grupos'!T26>'Fase de Grupos'!R26,1,0),0) | E18: =IF(AND(ISNUMBER('Fase de Grupos'!R22),ISNUMBER('Fase de Grupos'!T22)),IF('Fase de Grupos'!R22='Fase de Grupos'!T22,1,0),0)+IF(AND(ISNUMBER('Fase de Grupos'!R23),ISNUMBER('Fase de Grupos'!T23)),IF('Fase de Grupos'!R23='Fase de Grupos'!T23,1,0),0)+IF(AND(ISNUMBER('Fase de Grupos'!R26),ISNUMBER('Fase de Grupos'!T26)),IF('Fase de Grupos'!T26='Fase de Grupos'!R26,1,0),0) | F18: =IF(AND(ISNUMBER('Fase de Grupos'!R22),ISNUMBER('Fase de Grupos'!T22)),IF('Fase de Grupos'!R22<'Fase de Grupos'!T22,1,0),0)+IF(AND(ISNUMBER('Fase de Grupos'!R23),ISNUMBER('Fase de Grupos'!T23)),IF('Fase de Grupos'!R23<'Fase de Grupos'!T23,1,0),0)+IF(AND(ISNUMBER('Fase de Grupos'!R26),ISNUMBER('Fase de Grupos'!T26)),IF('Fase de Grupos'!T26<'Fase de Grupos'!R26,1,0),0) | G18: =SUM('Fase de Grupos'!R22,'Fase de Grupos'!R23,'Fase de Grupos'!T26) | H18: =SUM('Fase de Grupos'!T22,'Fase de Grupos'!T23,'Fase de Grupos'!R26) | I18: =G18-H18 | J18: =D18*3+E18 | K18: =J18*100000+(I18+1000)*100+G18*10+3
B19: Curazao | C19: =COUNT('Fase de Grupos'!R25,'Fase de Grupos'!T22,'Fase de Grupos'!T24) | D19: =IF(AND(ISNUMBER('Fase de Grupos'!R25),ISNUMBER('Fase de Grupos'!T25)),IF('Fase de Grupos'!R25>'Fase de Grupos'!T25,1,0),0)+IF(AND(ISNUMBER('Fase de Grupos'!R22),ISNUMBER('Fase de Grupos'!T22)),IF('Fase de Grupos'!T22>'Fase de Grupos'!R22,1,0),0)+IF(AND(ISNUMBER('Fase de Grupos'!R24),ISNUMBER('Fase de Grupos'!T24)),IF('Fase de Grupos'!T24>'Fase de Grupos'!R24,1,0),0) | E19: =IF(AND(ISNUMBER('Fase de Grupos'!R25),ISNUMBER('Fase de Grupos'!T25)),IF('Fase de Grupos'!R25='Fase de Grupos'!T25,1,0),0)+IF(AND(ISNUMBER('Fase de Grupos'!R22),ISNUMBER('Fase de Grupos'!T22)),IF('Fase de Grupos'!T22='Fase de Grupos'!R22,1,0),0)+IF(AND(ISNUMBER('Fase de Grupos'!R24),ISNUMBER('Fase de Grupos'!T24)),IF('Fase de Grupos'!T24='Fase de Grupos'!R24,1,0),0) | F19: =IF(AND(ISNUMBER('Fase de Grupos'!R25),ISNUMBER('Fase de Grupos'!T25)),IF('Fase de Grupos'!R25<'Fase de Grupos'!T25,1,0),0)+IF(AND(ISNUMBER('Fase de Grupos'!R22),ISNUMBER('Fase de Grupos'!T22)),IF('Fase de Grupos'!T22<'Fase de Grupos'!R22,1,0),0)+IF(AND(ISNUMBER('Fase de Grupos'!R24),ISNUMBER('Fase de Grupos'!T24)),IF('Fase de Grupos'!T24<'Fase de Grupos'!R24,1,0),0) | G19: =SUM('Fase de Grupos'!R25,'Fase de Grupos'!T22,'Fase de Grupos'!T24) | H19: =SUM('Fase de Grupos'!T25,'Fase de Grupos'!R22,'Fase de Grupos'!R24) | I19: =G19-H19 | J19: =D19*3+E19 | K19: =J19*100000+(I19+1000)*100+G19*10+2
B20: Costa de Marfil | C20: =COUNT('Fase de Grupos'!R21,'Fase de Grupos'!T23,'Fase de Grupos'!T25) | D20: =IF(AND(ISNUMBER('Fase de Grupos'!R21),ISNUMBER('Fase de Grupos'!T21)),IF('Fase de Grupos'!R21>'Fase de Grupos'!T21,1,0),0)+IF(AND(ISNUMBER('Fase de Grupos'!R23),ISNUMBER('Fase de Grupos'!T23)),IF('Fase de Grupos'!T23>'Fase de Grupos'!R23,1,0),0)+IF(AND(ISNUMBER('Fase de Grupos'!R25),ISNUMBER('Fase de Grupos'!T25)),IF('Fase de Grupos'!T25>'Fase de Grupos'!R25,1,0),0) | E20: =IF(AND(ISNUMBER('Fase de Grupos'!R21),ISNUMBER('Fase de Grupos'!T21)),IF('Fase de Grupos'!R21='Fase de Grupos'!T21,1,0),0)+IF(AND(ISNUMBER('Fase de Grupos'!R23),ISNUMBER('Fase de Grupos'!T23)),IF('Fase de Grupos'!T23='Fase de Grupos'!R23,1,0),0)+IF(AND(ISNUMBER('Fase de Grupos'!R25),ISNUMBER('Fase de Grupos'!T25)),IF('Fase de Grupos'!T25='Fase de Grupos'!R25,1,0),0) | F20: =IF(AND(ISNUMBER('Fase de Grupos'!R21),ISNUMBER('Fase de Grupos'!T21)),IF('Fase de Grupos'!R21<'Fase de Grupos'!T21,1,0),0)+IF(AND(ISNUMBER('Fase de Grupos'!R23),ISNUMBER('Fase de Grupos'!T23)),IF('Fase de Grupos'!T23<'Fase de Grupos'!R23,1,0),0)+IF(AND(ISNUMBER('Fase de Grupos'!R25),ISNUMBER('Fase de Grupos'!T25)),IF('Fase de Grupos'!T25<'Fase de Grupos'!R25,1,0),0) | G20: =SUM('Fase de Grupos'!R21,'Fase de Grupos'!T23,'Fase de Grupos'!T25) | H20: =SUM('Fase de Grupos'!T21,'Fase de Grupos'!R23,'Fase de Grupos'!R25) | I20: =G20-H20 | J20: =D20*3+E20 | K20: =J20*100000+(I20+1000)*100+G20*10+1
A21: F | B21: Ecuador | C21: =COUNT('Fase de Grupos'!R24,'Fase de Grupos'!R26,'Fase de Grupos'!T21) | D21: =IF(AND(ISNUMBER('Fase de Grupos'!R24),ISNUMBER('Fase de Grupos'!T24)),IF('Fase de Grupos'!R24>'Fase de Grupos'!T24,1,0),0)+IF(AND(ISNUMBER('Fase de Grupos'!R26),ISNUMBER('Fase de Grupos'!T26)),IF('Fase de Grupos'!R26>'Fase de Grupos'!T26,1,0),0)+IF(AND(ISNUMBER('Fase de Grupos'!R21),ISNUMBER('Fase de Grupos'!T21)),IF('Fase de Grupos'!T21>'Fase de Grupos'!R21,1,0),0) | E21: =IF(AND(ISNUMBER('Fase de Grupos'!R24),ISNUMBER('Fase de Grupos'!T24)),IF('Fase de Grupos'!R24='Fase de Grupos'!T24,1,0),0)+IF(AND(ISNUMBER('Fase de Grupos'!R26),ISNUMBER('Fase de Grupos'!T26)),IF('Fase de Grupos'!R26='Fase de Grupos'!T26,1,0),0)+IF(AND(ISNUMBER('Fase de Grupos'!R21),ISNUMBER('Fase de Grupos'!T21)),IF('Fase de Grupos'!T21='Fase de Grupos'!R21,1,0),0) | F21: =IF(AND(ISNUMBER('Fase de Grupos'!R24),ISNUMBER('Fase de Grupos'!T24)),IF('Fase de Grupos'!R24<'Fase de Grupos'!T24,1,0),0)+IF(AND(ISNUMBER('Fase de Grupos'!R26),ISNUMBER('Fase de Grupos'!T26)),IF('Fase de Grupos'!R26<'Fase de Grupos'!T26,1,0),0)+IF(AND(ISNUMBER('Fase de Grupos'!R21),ISNUMBER('Fase de Grupos'!T21)),IF('Fase de Grupos'!T21<'Fase de Grupos'!R21,1,0),0) | G21: =SUM('Fase de Grupos'!R24,'Fase de Grupos'!R26,'Fase de Grupos'!T21) | H21: =SUM('Fase de Grupos'!T24,'Fase de Grupos'!T26,'Fase de Grupos'!R21) | I21: =G21-H21 | J21: =D21*3+E21 | K21: =J21*100000+(I21+1000)*100+G21*10+0
B22: Países Bajos | C22: =COUNT('Fase de Grupos'!AC21,'Fase de Grupos'!AC23,'Fase de Grupos'!AE26) | D22: =IF(AND(ISNUMBER('Fase de Grupos'!AC21),ISNUMBER('Fase de Grupos'!AE21)),IF('Fase de Grupos'!AC21>'Fase de Grupos'!AE21,1,0),0)+IF(AND(ISNUMBER('Fase de Grupos'!AC23),ISNUMBER('Fase de Grupos'!AE23)),IF('Fase de Grupos'!AC23>'Fase de Grupos'!AE23,1,0),0)+IF(AND(ISNUMBER('Fase de Grupos'!AC26),ISNUMBER('Fase de Grupos'!AE26)),IF('Fase de Grupos'!AE26>'Fase de Grupos'!AC26,1,0),0) | E22: =IF(AND(ISNUMBER('Fase de Grupos'!AC21),ISNUMBER('Fase de Grupos'!AE21)),IF('Fase de Grupos'!AC21='Fase de Grupos'!AE21,1,0),0)+IF(AND(ISNUMBER('Fase de Grupos'!AC23),ISNUMBER('Fase de Grupos'!AE23)),IF('Fase de Grupos'!AC23='Fase de Grupos'!AE23,1,0),0)+IF(AND(ISNUMBER('Fase de Grupos'!AC26),ISNUMBER('Fase de Grupos'!AE26)),IF('Fase de Grupos'!AE26='Fase de Grupos'!AC26,1,0),0) | F22: =IF(AND(ISNUMBER('Fase de Grupos'!AC21),ISNUMBER('Fase de Grupos'!AE21)),IF('Fase de Grupos'!AC21<'Fase de Grupos'!AE21,1,0),0)+IF(AND(ISNUMBER('Fase de Grupos'!AC23),ISNUMBER('Fase de Grupos'!AE23)),IF('Fase de Grupos'!AC23<'Fase de Grupos'!AE23,1,0),0)+IF(AND(ISNUMBER('Fase de Grupos'!AC26),ISNUMBER('Fase de Grupos'!AE26)),IF('Fase de Grupos'!AE26<'Fase de Grupos'!AC26,1,0),0) | G22: =SUM('Fase de Grupos'!AC21,'Fase de Grupos'!AC23,'Fase de Grupos'!AE26) | H22: =SUM('Fase de Grupos'!AE21,'Fase de Grupos'!AE23,'Fase de Grupos'!AC26) | I22: =G22-H22 | J22: =D22*3+E22 | K22: =J22*100000+(I22+1000)*100+G22*10+3
